Workbook

Sheet 出力用
C4: =支点応力まとめ!AQ6 -> Y方向 | D4: =支点応力まとめ!AR6 -> X方向 | E4: 一貫計算：柱脚応力 | J4: 杭
E5: =支点応力まとめ!AS6 -> XL柱脚Q(kN) | F5: =支点応力まとめ!AT6 -> XR柱脚Q(kN) | G5: =支点応力まとめ!AU6 -> YL柱脚Q(kN) | H5: =支点応力まとめ!AV6 -> YR柱脚Q(kN) | I5: =支点応力まとめ!AW6&"Nc(kN)" -> 長期柱軸力Nc(kN) | J5: =支点応力まとめ!BA6&" NL" -> 長期支点反力(kN) NL
C6: =支点応力まとめ!AY7 -> Y1 | D6: =支点応力まとめ!AZ7 -> x21 | E6: =支点応力まとめ!AS7 -> 949.6 | F6: =支点応力まとめ!AT7 -> -48.4 | G6: =支点応力まとめ!AU7 -> 870.6 | H6: =支点応力まとめ!AV7 -> -5 | I6: =支点応力まとめ!AW7 -> 1108.5 | J6: =支点応力まとめ!BA7 -> 2460.4
C7: =支点応力まとめ!AY8 -> Y2 | D7: =支点応力まとめ!AZ8 -> x21 | E7: =支点応力まとめ!AS8 -> 49.6 | F7: =支点応力まとめ!AT8 -> -49.1 | G7: =支点応力まとめ!AU8 -> 5.4 | H7: =支点応力まとめ!AV8 -> -829 | I7: =支点応力まとめ!AW8 -> 1876.8 | J7: =支点応力まとめ!BA8 -> 3459.4
C8: =支点応力まとめ!AY9 -> Y3 | D8: =支点応力まとめ!AZ9 -> x21 | E8: =支点応力まとめ!AS9 -> 49.6 | F8: =支点応力まとめ!AT9 -> -48.5 | G8: =支点応力まとめ!AU9 -> 18.1 | H8: =支点応力まとめ!AV9 -> -18.8 | I8: =支点応力まとめ!AW9 -> 1357.5 | J8: =支点応力まとめ!BA9 -> 2588.4
C9: =支点応力まとめ!AY10 -> Y4 | D9: =支点応力まとめ!AZ10 -> x21 | E9: =支点応力まとめ!AS10 -> 2.3 | F9: =支点応力まとめ!AT10 -> -2.2 | G9: =支点応力まとめ!AU10 -> 19.6 | H9: =支点応力まとめ!AV10 -> -19.2 | I9: =支点応力まとめ!AW10 -> 898.5 | J9: =支点応力まとめ!BA10 -> 1731.7
C10: =支点応力まとめ!AY11 -> Y5 | D10: =支点応力まとめ!AZ11 -> x21 | E10: =支点応力まとめ!AS11 -> 2.9 | F10: =支点応力まとめ!AT11 -> -2.8 | G10: =支点応力まとめ!AU11 -> 29.9 | H10: =支点応力まとめ!AV11 -> -29.7 | I10: =支点応力まとめ!AW11 -> 893.1 | J10: =支点応力まとめ!BA11 -> 1736.7
C11: =支点応力まとめ!AY12 -> Y6 | D11: =支点応力まとめ!AZ12 -> x21 | E11: =支点応力まとめ!AS12 -> 523.6 | F11: =支点応力まとめ!AT12 -> -5.8 | G11: =支点応力まとめ!AU12 -> 61 | H11: =支点応力まとめ!AV12 -> -60.5 | I11: =支点応力まとめ!AW12 -> 781.8 | J11: =支点応力まとめ!BA12 -> 1613.5
C12: =支点応力まとめ!AY13 -> Y7 | D12: =支点応力まとめ!AZ13 -> x21 | E12: =支点応力まとめ!AS13 -> 31.7 | F12: =支点応力まとめ!AT13 -> -6.1 | G12: =支点応力まとめ!AU13 -> 44.5 | H12: =支点応力まとめ!AV13 -> -43 | I12: =支点応力まとめ!AW13 -> 400 | J12: =支点応力まとめ!BA13 -> 2414.7
C13: =支点応力まとめ!AY14 -> Y8 | D13: =支点応力まとめ!AZ14 -> x21 | E13: 0 | F13: 0 | G13: 0 | H13: 0 | I13: 0 | J13: =支点応力まとめ!BA14 -> 2189.1
C14: =支点応力まとめ!AY15 -> Y9 | D14: =支点応力まとめ!AZ15 -> x21 | E14: 0 | F14: 0 | G14: 0 | H14: 0 | I14: 0 | J14: =支点応力まとめ!BA15 -> 2113.2
C15: =支点応力まとめ!AY16 -> Y10 | D15: =支点応力まとめ!AZ16 -> x21 | E15: 0 | F15: 0 | G15: 0 | H15: 0 | I15: 0 | J15: =支点応力まとめ!BA16 -> 953.5
C16: =支点応力まとめ!AY17 -> Y1 | D16: =支点応力まとめ!AZ17 -> x22 | E16: =支点応力まとめ!AS14 -> 41.6 | F16: =支点応力まとめ!AT14 -> -988.4 | G16: =支点応力まとめ!AU14 -> 4.5 | H16: =支点応力まとめ!AV14 -> -4.5 | I16: =支点応力まとめ!AW14 -> 407.1 | J16: =支点応力まとめ!BA17 -> 1523
C17: =支点応力まとめ!AY18 -> Y2 | D17: =支点応力まとめ!AZ18 -> x22 | E17: =支点応力まとめ!AS15 -> 46.7 | F17: =支点応力まとめ!AT15 -> -45.7 | G17: =支点応力まとめ!AU15 -> 4.6 | H17: =支点応力まとめ!AV15 -> -4.4 | I17: =支点応力まとめ!AW15 -> 691.4 | J17: =支点応力まとめ!BA18 -> 2087
C18: =支点応力まとめ!AY19 -> Y3 | D18: =支点応力まとめ!AZ19 -> x22 | E18: =支点応力まとめ!AS16 -> 44.2 | F18: =支点応力まとめ!AT16 -> -43.2 | G18: =支点応力まとめ!AU16 -> 16.9 | H18: =支点応力まとめ!AV16 -> -16.4 | I18: =支点応力まとめ!AW16 -> 702.4 | J18: =支点応力まとめ!BA19 -> 1460.1
C19: =支点応力まとめ!AY20 -> Y4 | D19: =支点応力まとめ!AZ20 -> x22 | E19: =支点応力まとめ!AS17 -> 2.3 | F19: =支点応力まとめ!AT17 -> -2.2 | G19: =支点応力まとめ!AU17 -> 18.3 | H19: =支点応力まとめ!AV17 -> -18 | I19: =支点応力まとめ!AW17 -> 895.1 | J19: =支点応力まとめ!BA20 -> 1732.1
C20: =支点応力まとめ!AY21 -> Y5 | D20: =支点応力まとめ!AZ21 -> x22 | E20: =支点応力まとめ!AS18 -> 2.9 | F20: =支点応力まとめ!AT18 -> -2.8 | G20: =支点応力まとめ!AU18 -> 28.7 | H20: =支点応力まとめ!AV18 -> -26.7 | I20: =支点応力まとめ!AW18 -> 895.1 | J20: =支点応力まとめ!BA21 -> 1735.5
C21: =支点応力まとめ!AY22 -> Y6 | D21: =支点応力まとめ!AZ22 -> x22 | E21: =支点応力まとめ!AS19 -> 5.9 | F21: =支点応力まとめ!AT19 -> -512.9 | G21: =支点応力まとめ!AU19 -> 738.6 | H21: =支点応力まとめ!AV19 -> -52.1 | I21: =支点応力まとめ!AW19 -> 783.1 | J21: =支点応力まとめ!BA22 -> 1627.3
C22: =支点応力まとめ!AY23 -> Y7 | D22: =支点応力まとめ!AZ23 -> x22 | E22: =支点応力まとめ!AS20 -> 6.2 | F22: =支点応力まとめ!AT20 -> -30.8 | G22: =支点応力まとめ!AU20 -> 34.3 | H22: =支点応力まとめ!AV20 -> -744.3 | I22: =支点応力まとめ!AW20 -> 401.9 | J22: =支点応力まとめ!BA23 -> 1924.9
C23: =支点応力まとめ!AY24 -> Y8 | D23: =支点応力まとめ!AZ24 -> x22 | E23: 0 | F23: 0 | G23: 0 | H23: 0 | I23: 0 | J23: =支点応力まとめ!BA24 -> 2186.8
C24: =支点応力まとめ!AY25 -> Y9 | D24: =支点応力まとめ!AZ25 -> x22 | E24: 0 | F24: 0 | G24: 0 | H24: 0 | I24: 0 | J24: =支点応力まとめ!BA25 -> 2113.7
C25: =支点応力まとめ!AY26 -> Y10 | D25: =支点応力まとめ!AZ26 -> x22 | E25: 0 | F25: 0 | G25: 0 | H25: 0 | I25: 0 | J25: =支点応力まとめ!BA26 -> 953.5

Sheet 支点応力まとめ
A6: フーチング | B6: 整理名称 | C6: 軸 | D6: 通 | E6: 長期 | F6: 軸 | G6: 通 | H6: 短期 max | I6: 軸 | J6: 通 | K6: 短期 min | X6: Qc | Y6: N | Z6: Nc | AA6: Qs | AE6: Qc | AF6: N | AG6: Nc | AH6: Qs | AL6: Qc | AM6: N | AN6: Nc | AO6: Qs | AQ6: {=柱脚応力!B1:C15} -> Y方向 | AR6: X方向 | AS6: {=柱脚応力!F1:F15} -> XL柱脚Q(kN) | AT6: {=柱脚応力!I1:I15} -> XR柱脚Q(kN) | AU6: {=柱脚応力!L1:L15} -> YL柱脚Q(kN) | AV6: {=柱脚応力!O1:O15} -> YR柱脚Q(kN) | AW6: {=柱脚応力!Q1:Q15} -> 長期柱軸力 | AY6: 通 | AZ6: 軸 | BA6: 長期支点反力(kN) | BD6: ** | BF6: Y1 | BG6: Y2 | BH6: Y3 | BI6: Y4 | BJ6: Y5 | BK6: Y6 | BL6: y7 | BM6: y8 | BN6: Y9 | BO6: Y10
M7: 長期参照 | N7: F名 | O7: max参照 | P7: F名 | Q7: min参照 | R7: F名 | S7: 長期チェック | T7: maxチェック | U7: minチェック | W7: XL | X7: =ABS(SUMIFS(柱脚応力!$F:$F,柱脚応力!$C:$C,"x2?")) -> 1759.1 | Y7: =SUMIFS($E$33:$E$152,$C$33:$C$152,"x2?") -> 38604.5 | Z7: =SUMIFS(柱脚応力!$Q:$Q,柱脚応力!$C:$C,"x2?") -> 12092.3 | AA7: =X7+0.1*0.9*(Y7-Z7) -> 4145.198 | AC7: YL | AD7: X21-Y1/Y2 | AE7: =SUM(AU7:AU8) -> 876 | AF7: =SUM($BA$7:$BA$8) -> 5919.8 | AG7: =SUM(AW7:AW8) -> 2985.3 | AH7: =AE7+0.1*0.9*(AF7-AG7) -> 1140.105 | AJ7: XL | AK7: Y1 | AL7: =ABS(SUMIFS(柱脚応力!$F:$F,柱脚応力!$C:$C,"x2?",柱脚応力!$B:$B,AK7)) -> 991.2 | AM7: =SUMIFS($E$33:$E$152,$C$33:$C$152,"x2?",$B$33:$B$152,AK7) -> 3983.4 | AN7: =SUMIFS(柱脚応力!$Q:$Q, 柱脚応力!$C:$C,"x2?",柱脚応力!$B:$B,AK7) -> 1515.6 | AO7: =AL7+0.1*0.9*(AM7-AN7) -> 1213.302 | AQ7: y1 | AR7: x21 | AS7: 949.6 | AT7: -48.4 | AU7: 870.6 | AV7: -5 | AW7: 1108.5 | AY7: Y1 | AZ7: x21 | BA7: =$E$43 -> 2460.4 | BD7: AXL2 | BE7: X22 | BF7: 200 | BG7: 200 | BH7: 200 | BI7: 200 | BJ7: 200 | BK7: 200 | BL7: 200 | BM7: 200 | BN7: 200 | BO7: 200
A8: F10,F10A,F10B,F10C | B8: F10 | C8: {=INDEX($B$33:$B$156,M8)} -> y8 | D8: {=INDEX($C$33:$C$156,M8)} -> x9 | E8: {=MAX(IF($AC$33:$AC$156=$B8,$Z$33:$Z$156,""))} -> 5244.2 | F8: {=INDEX($B$33:$B$156,O8)} -> y2 | G8: {=INDEX($C$33:$C$156,O8)} -> x7 | H8: {=MAX(IF($AC$33:$AC$156=$B8,$AA$33:$AA$156,""))} -> 6396.35 | I8: {=INDEX($B$33:$B$156,Q8)} -> y1 | J8: {=INDEX($C$33:$C$156,Q8)} -> x22 | K8: {=MIN(IF($AC$33:$AC$156=$B8,$AB$33:$AB$156,""))} -> 703.9 | M8: {=MATCH(MAX(IF($AC$33:$AC$156=$B8,$Z$33:$Z$156,"")),$Z$33:$Z$156,0)} -> 93 | N8: {=INDEX($AC$33:$AC$156,M8)} -> F10 | O8: {=MATCH(MAX(IF($AC$33:$AC$156=$B8,$AA$33:$AA$156,"")),$AA$33:$AA$156,0)} -> 19 | P8: {=INDEX($AC$33:$AC$156,O8)} -> F10 | Q8: {=MATCH(MIN(IF($AC$33:$AC$156=$B8,$AB$33:$AB$156,"")),$AB$33:$AB$156,0)} -> 12 | R8: {=INDEX($AC$33:$AC$156,Q8)} -> F10 | S8: =IF($B8=N8,"OK","NG") -> OK | T8: =IF($B8=P8,"OK","NG") -> OK | U8: =IF($B8=R8,"OK","NG") -> OK | W8: XR | X8: =ABS(SUMIFS(柱脚応力!$I:$I,柱脚応力!$C:$C,"x2?")) -> 1788.9 | Y8: =SUMIFS($E$33:$E$152,$C$33:$C$152,"x2?") -> 38604.5 | Z8: =SUMIFS(柱脚応力!$Q:$Q,柱脚応力!$C:$C,"x2?") -> 12092.3 | AA8: =X8+0.1*0.9*(Y8-Z8) -> 4174.998 | AC8: YL | AD8: X21-Y3/Y6 | AE8: =SUM(AU9:AU12) -> 128.6 | AF8: =SUM($BA$9:$BA$12) -> 7670.3 | AG8: =SUM(AW9:AW12) -> 3930.9 | AH8: =AE8+0.1*0.9*(AF8-AG8) -> 465.146 | AJ8: XL | AK8: Y2 | AL8: =ABS(SUMIFS(柱脚応力!$F:$F,柱脚応力!$C:$C,"x2?",柱脚応力!$B:$B,AK8)) -> 96.3 | AM8: =SUMIFS($E$33:$E$152,$C$33:$C$152,"x2?",$B$33:$B$152,AK8) -> 5546.4 | AN8: =SUMIFS(柱脚応力!$Q:$Q, 柱脚応力!$C:$C,"x2?",柱脚応力!$B:$B,AK8) -> 2568.2 | AO8: =AL8+0.1*0.9*(AM8-AN8) -> 364.338 | AQ8: y2 | AR8: x21 | AS8: 49.6 | AT8: -49.1 | AU8: 5.4 | AV8: -829 | AW8: 1876.8 | AY8: Y2 | AZ8: x21 | BA8: =$E$55 -> 3459.4 | BD8: AXL2 | BE8: X21 | BF8: 200 | BG8: 200 | BH8: 200 | BI8: 200 | BJ8: 200 | BK8: 200 | BL8: 200 | BM8: 200 | BN8: 200 | BO8: 200
A9: F11 | B9: F11 | C9: {=INDEX($B$33:$B$156,M9)} -> y9 | D9: {=INDEX($C$33:$C$156,M9)} -> x9 | E9: {=MAX(IF($AC$33:$AC$156=$B9,$Z$33:$Z$156,""))} -> 4240.1 | F9: {=INDEX($B$33:$B$156,O9)} -> y9 | G9: {=INDEX($C$33:$C$156,O9)} -> x9 | H9: {=MAX(IF($AC$33:$AC$156=$B9,$AA$33:$AA$156,""))} -> 5163.35 | I9: {=INDEX($B$33:$B$156,Q9)} -> y9 | J9: {=INDEX($C$33:$C$156,Q9)} -> x9 | K9: {=MIN(IF($AC$33:$AC$156=$B9,$AB$33:$AB$156,""))} -> 3591 | M9: {=MATCH(MAX(IF($AC$33:$AC$156=$B9,$Z$33:$Z$156,"")),$Z$33:$Z$156,0)} -> 105 | N9: {=INDEX($AC$33:$AC$156,M9)} -> F11 | O9: {=MATCH(MAX(IF($AC$33:$AC$156=$B9,$AA$33:$AA$156,"")),$AA$33:$AA$156,0)} -> 105 | P9: {=INDEX($AC$33:$AC$156,O9)} -> F11 | Q9: {=MATCH(MIN(IF($AC$33:$AC$156=$B9,$AB$33:$AB$156,"")),$AB$33:$AB$156,0)} -> 105 | R9: {=INDEX($AC$33:$AC$156,Q9)} -> F11 | S9: =IF($B9=N9,"OK","NG") -> OK | T9: =IF($B9=P9,"OK","NG") -> OK | U9: =IF($B9=R9,"OK","NG") -> OK | W9: YL | X9: =ABS(SUMIFS(柱脚応力!$L:$L,柱脚応力!$C:$C,"x2?")) -> 1895 | Y9: =SUMIFS($E$33:$E$152,$C$33:$C$152,"x2?") -> 38604.5 | Z9: =SUMIFS(柱脚応力!$Q:$Q,柱脚応力!$C:$C,"x2?") -> 12092.3 | AA9: =X9+0.1*0.9*(Y9-Z9) -> 4281.098 | AC9: YL | AD9: X21-Y7/Y10 | AE9: =SUM(AU13) -> 44.5 | AF9: =SUM($BA$13:$BA$16) -> 7670.5 | AG9: =SUM(AW13) -> 400 | AH9: =AE9+0.1*0.9*(AF9-AG9) -> 698.845 | AJ9: XL | AK9: Y3 | AL9: =ABS(SUMIFS(柱脚応力!$F:$F,柱脚応力!$C:$C,"x2?",柱脚応力!$B:$B,AK9)) -> 93.8 | AM9: =SUMIFS($E$33:$E$152,$C$33:$C$152,"x2?",$B$33:$B$152,AK9) -> 4048.5 | AN9: =SUMIFS(柱脚応力!$Q:$Q, 柱脚応力!$C:$C,"x2?",柱脚応力!$B:$B,AK9) -> 2059.9 | AO9: =AL9+0.1*0.9*(AM9-AN9) -> 272.774 | AQ9: y3 | AR9: x21 | AS9: 49.6 | AT9: -48.5 | AU9: 18.1 | AV9: -18.8 | AW9: 1357.5 | AY9: Y3 | AZ9: x21 | BA9: =$E$67 -> 2588.4 | BD9: AXL2 | BE9: X10 | BF9: 280 | BG9: 280 | BH9: 280 | BI9: 280 | BJ9: 280 | BK9: 280 | BL9: 280 | BM9: 280 | BN9: 280 | BO9: 280
A10: F20A,F20C,F20D | B10: F20 | C10: {=INDEX($B$33:$B$156,M10)} -> y7 | D10: {=INDEX($C$33:$C$156,M10)} -> x10 | E10: {=MAX(IF($AC$33:$AC$156=$B10,$Z$33:$Z$156,""))} -> 3364.8 | F10: {=INDEX($B$33:$B$156,O10)} -> y1 | G10: {=INDEX($C$33:$C$156,O10)} -> x4 | H10: {=MAX(IF($AC$33:$AC$156=$B10,$AA$33:$AA$156,""))} -> 4662.95 | I10: {=INDEX($B$33:$B$156,Q10)} -> y6 | J10: {=INDEX($C$33:$C$156,Q10)} -> x21 | K10: {=MIN(IF($AC$33:$AC$156=$B10,$AB$33:$AB$156,""))} -> 1279.9 | M10: {=MATCH(MAX(IF($AC$33:$AC$156=$B10,$Z$33:$Z$156,"")),$Z$33:$Z$156,0)} -> 82 | N10: {=INDEX($AC$33:$AC$156,M10)} -> F20 | O10: {=MATCH(MAX(IF($AC$33:$AC$156=$B10,$AA$33:$AA$156,"")),$AA$33:$AA$156,0)} -> 4 | P10: {=INDEX($AC$33:$AC$156,O10)} -> F20 | Q10: {=MATCH(MIN(IF($AC$33:$AC$156=$B10,$AB$33:$AB$156,"")),$AB$33:$AB$156,0)} -> 71 | R10: {=INDEX($AC$33:$AC$156,Q10)} -> F20 | S10: =IF($B10=N10,"OK","NG") -> OK | T10: =IF($B10=P10,"OK","NG") -> OK | U10: =IF($B10=R10,"OK","NG") -> OK | W10: YR | X10: =ABS(SUMIFS(柱脚応力!$O:$O,柱脚応力!$C:$C,"x2?")) -> 1871.6 | Y10: =SUMIFS($E$33:$E$152,$C$33:$C$152,"x2?") -> 38604.5 | Z10: =SUMIFS(柱脚応力!$Q:$Q,柱脚応力!$C:$C,"x2?") -> 12092.3 | AA10: =X10+0.1*0.9*(Y10-Z10) -> 4257.698 | AC10: YL | AD10: X22-Y1/Y2 | AE10: =SUM(AU14:AU15) -> 9.1 | AF10: =SUM($BA$17:$BA$18) -> 3610 | AG10: =SUM(AW14:AW15) -> 1098.5 | AH10: =AE10+0.1*0.9*(AF10-AG10) -> 235.135 | AJ10: XL | AK10: Y4 | AL10: =ABS(SUMIFS(柱脚応力!$F:$F,柱脚応力!$C:$C,"x2?",柱脚応力!$B:$B,AK10)) -> 4.6 | AM10: =SUMIFS($E$33:$E$152,$C$33:$C$152,"x2?",$B$33:$B$152,AK10) -> 3463.8 | AN10: =SUMIFS(柱脚応力!$Q:$Q, 柱脚応力!$C:$C,"x2?",柱脚応力!$B:$B,AK10) -> 1793.6 | AO10: =AL10+0.1*0.9*(AM10-AN10) -> 154.918 | AQ10: y4 | AR10: x21 | AS10: 2.3 | AT10: -2.2 | AU10: 19.6 | AV10: -19.2 | AW10: 898.5 | AY10: Y4 | AZ10: x21 | BA10: =$E$79 -> 1731.7 | BD10: AXL2 | BE10: X9 | BF10: 300 | BG10: 300 | BH10: 300 | BI10: 300 | BJ10: 300 | BK10: 300 | BL10: 300 | BM10: 300 | BN10: 300 | BO10: 300
A11: F21,F21B,F21C | B11: F21 | C11: {=INDEX($B$33:$B$156,M11)} -> y10 | D11: {=INDEX($C$33:$C$156,M11)} -> x2 | E11: {=MAX(IF($AC$33:$AC$156=$B11,$Z$33:$Z$156,""))} -> 3192.1 | F11: {=INDEX($B$33:$B$156,O11)} -> y1 | G11: {=INDEX($C$33:$C$156,O11)} -> x7 | H11: {=MAX(IF($AC$33:$AC$156=$B11,$AA$33:$AA$156,""))} -> 4859.7 | I11: {=INDEX($B$33:$B$156,Q11)} -> y5 | J11: {=INDEX($C$33:$C$156,Q11)} -> x1 | K11: {=MIN(IF($AC$33:$AC$156=$B11,$AB$33:$AB$156,""))} -> 1365.8 | M11: {=MATCH(MAX(IF($AC$33:$AC$156=$B11,$Z$33:$Z$156,"")),$Z$33:$Z$156,0)} -> 110 | N11: {=INDEX($AC$33:$AC$156,M11)} -> F21 | O11: {=MATCH(MAX(IF($AC$33:$AC$156=$B11,$AA$33:$AA$156,"")),$AA$33:$AA$156,0)} -> 7 | P11: {=INDEX($AC$33:$AC$156,O11)} -> F21 | Q11: {=MATCH(MIN(IF($AC$33:$AC$156=$B11,$AB$33:$AB$156,"")),$AB$33:$AB$156,0)} -> 49 | R11: {=INDEX($AC$33:$AC$156,Q11)} -> F21 | S11: =IF($B11=N11,"OK","NG") -> OK | T11: =IF($B11=P11,"OK","NG") -> OK | U11: =IF($B11=R11,"OK","NG") -> OK | AC11: YL | AD11: X22-Y3/Y6 | AE11: =SUM(AU16:AU19) -> 802.5 | AF11: =SUM($BA$19:$BA$22) -> 6555 | AG11: =SUM(AW16:AW19) -> 3275.7 | AH11: =AE11+0.1*0.9*(AF11-AG11) -> 1097.637 | AJ11: XL | AK11: Y5 | AL11: =ABS(SUMIFS(柱脚応力!$F:$F,柱脚応力!$C:$C,"x2?",柱脚応力!$B:$B,AK11)) -> 5.8 | AM11: =SUMIFS($E$33:$E$152,$C$33:$C$152,"x2?",$B$33:$B$152,AK11) -> 3472.2 | AN11: =SUMIFS(柱脚応力!$Q:$Q, 柱脚応力!$C:$C,"x2?",柱脚応力!$B:$B,AK11) -> 1788.2 | AO11: =AL11+0.1*0.9*(AM11-AN11) -> 157.36 | AQ11: y5 | AR11: x21 | AS11: 2.9 | AT11: -2.8 | AU11: 29.9 | AV11: -29.7 | AW11: 893.1 | AY11: Y5 | AZ11: x21 | BA11: =$E$91 -> 1736.7 | BD11: AXL2 | BE11: X8 | BF11: 280 | BG11: 210 | BH11: 210 | BI11: 210 | BJ11: 210 | BK11: 210 | BL11: 210 | BM11: 210 | BN11: 210 | BO11: 280
A12: F30,F30B,F30C | B12: F30 | C12: {=INDEX($B$33:$B$156,M12)} -> y9 | D12: {=INDEX($C$33:$C$156,M12)} -> x10 | E12: {=MAX(IF($AC$33:$AC$156=$B12,$Z$33:$Z$156,""))} -> 2471.5 | F12: {=INDEX($B$33:$B$156,O12)} -> y10 | G12: {=INDEX($C$33:$C$156,O12)} -> x7 | H12: {=MAX(IF($AC$33:$AC$156=$B12,$AA$33:$AA$156,""))} -> 4174 | I12: {=INDEX($B$33:$B$156,Q12)} -> y1 | J12: {=INDEX($C$33:$C$156,Q12)} -> x1 | K12: {=MIN(IF($AC$33:$AC$156=$B12,$AB$33:$AB$156,""))} -> 623.1 | M12: {=MATCH(MAX(IF($AC$33:$AC$156=$B12,$Z$33:$Z$156,"")),$Z$33:$Z$156,0)} -> 106 | N12: {=INDEX($AC$33:$AC$156,M12)} -> F30 | O12: {=MATCH(MAX(IF($AC$33:$AC$156=$B12,$AA$33:$AA$156,"")),$AA$33:$AA$156,0)} -> 115 | P12: {=INDEX($AC$33:$AC$156,O12)} -> F30 | Q12: {=MATCH(MIN(IF($AC$33:$AC$156=$B12,$AB$33:$AB$156,"")),$AB$33:$AB$156,0)} -> 1 | R12: {=INDEX($AC$33:$AC$156,Q12)} -> F30 | S12: =IF($B12=N12,"OK","NG") -> OK | T12: =IF($B12=P12,"OK","NG") -> OK | U12: =IF($B12=R12,"OK","NG") -> OK | X12: Qall | Y12: Qs | Z12: Qm | AA12: 決定本体 | AC12: YL | AD12: X22-Y7/Y10 | AE12: =SUM(AU20) -> 34.3 | AF12: =SUM($BA$23:$BA$26) -> 7178.9 | AG12: =SUM(AW20) -> 401.9 | AH12: =AE12+0.1*0.9*(AF12-AG12) -> 644.23 | AJ12: XL | AK12: Y6 | AL12: =ABS(SUMIFS(柱脚応力!$F:$F,柱脚応力!$C:$C,"x2?",柱脚応力!$B:$B,AK12)) -> 529.5 | AM12: =SUMIFS($E$33:$E$152,$C$33:$C$152,"x2?",$B$33:$B$152,AK12) -> 3240.8 | AN12: =SUMIFS(柱脚応力!$Q:$Q, 柱脚応力!$C:$C,"x2?",柱脚応力!$B:$B,AK12) -> 1564.9 | AO12: =AL12+0.1*0.9*(AM12-AN12) -> 680.331 | AQ12: y6 | AR12: x21 | AS12: 523.6 | AT12: -5.8 | AU12: 61 | AV12: -60.5 | AW12: 781.8 | AY12: Y6 | AZ12: x21 | BA12: =$E$103 -> 1613.5 | BD12: AXL2 | BE12: X7 | BF12: 280 | BG12: 210 | BH12: 210 | BI12: 210 | BJ12: 210 | BK12: 210 | BL12: 210 | BM12: 210 | BN12: 210 | BO12: 280
C13: {=INDEX($B$33:$B$156,M13)} -> 0 | D13: {=INDEX($C$33:$C$156,M13)} -> 0 | E13: {=MAX(IF($AC$33:$AC$156=$B13,$Z$33:$Z$156,""))} -> 0 | F13: {=INDEX($B$33:$B$156,O13)} -> 0 | G13: {=INDEX($C$33:$C$156,O13)} -> 0 | H13: {=MAX(IF($AC$33:$AC$156=$B13,$AA$33:$AA$156,""))} -> 0 | I13: {=INDEX($B$33:$B$156,Q13)} -> 0 | J13: {=INDEX($C$33:$C$156,Q13)} -> 0 | K13: {=MIN(IF($AC$33:$AC$156=$B13,$AB$33:$AB$156,""))} -> 0 | M13: {=MATCH(MAX(IF($AC$33:$AC$156=$B13,$Z$33:$Z$156,"")),$Z$33:$Z$156,0)} -> 121 | N13: {=INDEX($AC$33:$AC$156,M13)} -> 0 | O13: {=MATCH(MAX(IF($AC$33:$AC$156=$B13,$AA$33:$AA$156,"")),$AA$33:$AA$156,0)} -> 121 | P13: {=INDEX($AC$33:$AC$156,O13)} -> 0 | Q13: {=MATCH(MIN(IF($AC$33:$AC$156=$B13,$AB$33:$AB$156,"")),$AB$33:$AB$156,0)} -> 121 | R13: {=INDEX($AC$33:$AC$156,Q13)} -> 0 | S13: =IF($B13=N13,"OK","NG") -> OK | T13: =IF($B13=P13,"OK","NG") -> OK | U13: =IF($B13=R13,"OK","NG") -> OK | W13: XL | X13: =$J$29 -> 44000 | Y13: =AA7 -> 4145.198 | Z13: =X13-Y13 -> 39854.802 | AC13: YR | AD13: X21-Y1/Y2 | AE13: =-1*SUM(AV7:AV8) -> 834 | AF13: =SUM($BA$7:$BA$8) -> 5919.8 | AG13: =SUM(AW7:AW8) -> 2985.3 | AH13: =AE13+0.1*0.9*(AF13-AG13) -> 1098.105 | AJ13: XL | AK13: Y7 | AL13: =ABS(SUMIFS(柱脚応力!$F:$F,柱脚応力!$C:$C,"x2?",柱脚応力!$B:$B,AK13)) -> 37.9 | AM13: =SUMIFS($E$33:$E$152,$C$33:$C$152,"x2?",$B$33:$B$152,AK13) -> 4339.6 | AN13: =SUMIFS(柱脚応力!$Q:$Q, 柱脚応力!$C:$C,"x2?",柱脚応力!$B:$B,AK13) -> 801.9 | AO13: =AL13+0.1*0.9*(AM13-AN13) -> 356.293 | AQ13: y7 | AR13: x21 | AS13: 31.7 | AT13: -6.1 | AU13: 44.5 | AV13: -43 | AW13: 400 | AY13: Y7 | AZ13: x21 | BA13: =$E$115 -> 2414.7 | BD13: AXL2 | BE13: X6 | BF13: 280 | BG13: 210 | BH13: 210 | BI13: 210 | BJ13: 210 | BK13: 210 | BL13: 210 | BM13: 210 | BN13: 210 | BO13: 280
C14: {=INDEX($B$33:$B$156,M14)} -> 0 | D14: {=INDEX($C$33:$C$156,M14)} -> 0 | E14: {=MAX(IF($AC$33:$AC$156=$B14,$Z$33:$Z$156,""))} -> 0 | F14: {=INDEX($B$33:$B$156,O14)} -> 0 | G14: {=INDEX($C$33:$C$156,O14)} -> 0 | H14: {=MAX(IF($AC$33:$AC$156=$B14,$AA$33:$AA$156,""))} -> 0 | I14: {=INDEX($B$33:$B$156,Q14)} -> 0 | J14: {=INDEX($C$33:$C$156,Q14)} -> 0 | K14: {=MIN(IF($AC$33:$AC$156=$B14,$AB$33:$AB$156,""))} -> 0 | M14: {=MATCH(MAX(IF($AC$33:$AC$156=$B14,$Z$33:$Z$156,"")),$Z$33:$Z$156,0)} -> 121 | N14: {=INDEX($AC$33:$AC$156,M14)} -> 0 | O14: {=MATCH(MAX(IF($AC$33:$AC$156=$B14,$AA$33:$AA$156,"")),$AA$33:$AA$156,0)} -> 121 | P14: {=INDEX($AC$33:$AC$156,O14)} -> 0 | Q14: {=MATCH(MIN(IF($AC$33:$AC$156=$B14,$AB$33:$AB$156,"")),$AB$33:$AB$156,0)} -> 121 | R14: {=INDEX($AC$33:$AC$156,Q14)} -> 0 | S14: =IF($B14=N14,"OK","NG") -> OK | T14: =IF($B14=P14,"OK","NG") -> OK | U14: =IF($B14=R14,"OK","NG") -> OK | W14: XR | X14: =$J$29 -> 44000 | Y14: =AA8 -> 4174.998 | Z14: =X14-Y14 -> 39825.002 | AC14: YR | AD14: X21-Y3/Y6 | AE14: =SUM(AV9:AV12)*-1 -> 128.2 | AF14: =SUM($BA$9:$BA$12) -> 7670.3 | AG14: =SUM(AW9:AW12) -> 3930.9 | AH14: =AE14+0.1*0.9*(AF14-AG14) -> 464.746 | AJ14: XL | AK14: Y8 | AL14: =ABS(SUMIFS(柱脚応力!$F:$F,柱脚応力!$C:$C,"x2?",柱脚応力!$B:$B,AK14)) -> 0 | AM14: =SUMIFS($E$33:$E$152,$C$33:$C$152,"x2?",$B$33:$B$152,AK14) -> 4375.9 | AN14: =SUMIFS(柱脚応力!$Q:$Q, 柱脚応力!$C:$C,"x2?",柱脚応力!$B:$B,AK14) -> 0 | AO14: =AL14+0.1*0.9*(AM14-AN14) -> 393.831 | AQ14: y1 | AR14: x22 | AS14: 41.6 | AT14: -988.4 | AU14: 4.5 | AV14: -4.5 | AW14: 407.1 | AY14: Y8 | AZ14: x21 | BA14: =$E$127 -> 2189.1 | BD14: AXL2 | BE14: X5 | BF14: 280 | BG14: 210 | BH14: 210 | BI14: 210 | BJ14: 210 | BK14: 210 | BL14: 210 | BM14: 210 | BN14: 210 | BO14: 280
C15: {=INDEX($B$33:$B$156,M15)} -> 0 | D15: {=INDEX($C$33:$C$156,M15)} -> 0 | E15: {=MAX(IF($AC$33:$AC$156=$B15,$Z$33:$Z$156,""))} -> 0 | F15: {=INDEX($B$33:$B$156,O15)} -> 0 | G15: {=INDEX($C$33:$C$156,O15)} -> 0 | H15: {=MAX(IF($AC$33:$AC$156=$B15,$AA$33:$AA$156,""))} -> 0 | I15: {=INDEX($B$33:$B$156,Q15)} -> 0 | J15: {=INDEX($C$33:$C$156,Q15)} -> 0 | K15: {=MIN(IF($AC$33:$AC$156=$B15,$AB$33:$AB$156,""))} -> 0 | M15: {=MATCH(MAX(IF($AC$33:$AC$156=$B15,$Z$33:$Z$156,"")),$Z$33:$Z$156,0)} -> 121 | N15: {=INDEX($AC$33:$AC$156,M15)} -> 0 | O15: {=MATCH(MAX(IF($AC$33:$AC$156=$B15,$AA$33:$AA$156,"")),$AA$33:$AA$156,0)} -> 121 | P15: {=INDEX($AC$33:$AC$156,O15)} -> 0 | Q15: {=MATCH(MIN(IF($AC$33:$AC$156=$B15,$AB$33:$AB$156,"")),$AB$33:$AB$156,0)} -> 121 | R15: {=INDEX($AC$33:$AC$156,Q15)} -> 0 | S15: =IF($B15=N15,"OK","NG") -> OK | T15: =IF($B15=P15,"OK","NG") -> OK | U15: =IF($B15=R15,"OK","NG") -> OK | W15: YL | X15: =$J$29 -> 44000 | Y15: =AA9 -> 4281.098 | Z15: =X15-Y15 -> 39718.902 | AC15: YR | AD15: X21-Y7/Y10 | AE15: =SUM(AV13)*-1 -> 43 | AF15: =SUM($BA$13:$BA$16) -> 7670.5 | AG15: =SUM(AW13) -> 400 | AH15: =AE15+0.1*0.9*(AF15-AG15) -> 697.345 | AJ15: XL | AK15: Y9 | AL15: =ABS(SUMIFS(柱脚応力!$F:$F,柱脚応力!$C:$C,"x2?",柱脚応力!$B:$B,AK15)) -> 0 | AM15: =SUMIFS($E$33:$E$152,$C$33:$C$152,"x2?",$B$33:$B$152,AK15) -> 4226.9 | AN15: =SUMIFS(柱脚応力!$Q:$Q, 柱脚応力!$C:$C,"x2?",柱脚応力!$B:$B,AK15) -> 0 | AO15: =AL15+0.1*0.9*(AM15-AN15) -> 380.421 | AQ15: y2 | AR15: x22 | AS15: 46.7 | AT15: -45.7 | AU15: 4.6 | AV15: -4.4 | AW15: 691.4 | AY15: Y9 | AZ15: x21 | BA15: =$E$139 -> 2113.2 | BD15: AXL2 | BE15: X4 | BF15: 280 | BG15: 210 | BH15: 210 | BI15: 210 | BJ15: 210 | BK15: 210 | BL15: 210 | BM15: 210 | BN15: 210 | BO15: 280
C16: {=INDEX($B$33:$B$156,M16)} -> 0 | D16: {=INDEX($C$33:$C$156,M16)} -> 0 | E16: {=MAX(IF($AC$33:$AC$156=$B16,$Z$33:$Z$156,""))} -> 0 | F16: {=INDEX($B$33:$B$156,O16)} -> 0 | G16: {=INDEX($C$33:$C$156,O16)} -> 0 | H16: {=MAX(IF($AC$33:$AC$156=$B16,$AA$33:$AA$156,""))} -> 0 | I16: {=INDEX($B$33:$B$156,Q16)} -> 0 | J16: {=INDEX($C$33:$C$156,Q16)} -> 0 | K16: {=MIN(IF($AC$33:$AC$156=$B16,$AB$33:$AB$156,""))} -> 0 | M16: {=MATCH(MAX(IF($AC$33:$AC$156=$B16,$Z$33:$Z$156,"")),$Z$33:$Z$156,0)} -> 121 | N16: {=INDEX($AC$33:$AC$156,M16)} -> 0 | O16: {=MATCH(MAX(IF($AC$33:$AC$156=$B16,$AA$33:$AA$156,"")),$AA$33:$AA$156,0)} -> 121 | P16: {=INDEX($AC$33:$AC$156,O16)} -> 0 | Q16: {=MATCH(MIN(IF($AC$33:$AC$156=$B16,$AB$33:$AB$156,"")),$AB$33:$AB$156,0)} -> 121 | R16: {=INDEX($AC$33:$AC$156,Q16)} -> 0 | S16: =IF($B16=N16,"OK","NG") -> OK | T16: =IF($B16=P16,"OK","NG") -> OK | U16: =IF($B16=R16,"OK","NG") -> OK | W16: YR | X16: =$J$29 -> 44000 | Y16: =AA10 -> 4257.698 | Z16: =X16-Y16 -> 39742.302 | AA16: 41000 | AC16: YR | AD16: X22-Y1/Y2 | AE16: =SUM(AV14:AV15)*-1 -> 8.9 | AF16: =SUM($BA$17:$BA$18) -> 3610 | AG16: =SUM(AW14:AW15) -> 1098.5 | AH16: =AE16+0.1*0.9*(AF16-AG16) -> 234.935 | AJ16: XL | AK16: Y10 | AL16: =ABS(SUMIFS(柱脚応力!$F:$F,柱脚応力!$C:$C,"x2?",柱脚応力!$B:$B,AK16)) -> 0 | AM16: =SUMIFS($E$33:$E$152,$C$33:$C$152,"x2?",$B$33:$B$152,AK16) -> 1907 | AN16: =SUMIFS(柱脚応力!$Q:$Q, 柱脚応力!$C:$C,"x2?",柱脚応力!$B:$B,AK16) -> 0 | AO16: =AL16+0.1*0.9*(AM16-AN16) -> 171.63 | AQ16: y3 | AR16: x22 | AS16: 44.2 | AT16: -43.2 | AU16: 16.9 | AV16: -16.4 | AW16: 702.4 | AY16: Y10 | AZ16: x21 | BA16: =$E$151 -> 953.5 | BD16: AXL2 | BE16: X3 | BF16: 280 | BG16: 210 | BH16: 210 | BI16: 210 | BJ16: 210 | BK16: 210 | BL16: 210 | BM16: 210 | BN16: 210 | BO16: 280
C17: {=INDEX($B$33:$B$156,M17)} -> 0 | D17: {=INDEX($C$33:$C$156,M17)} -> 0 | E17: {=MAX(IF($AC$33:$AC$156=$B17,$Z$33:$Z$156,""))} -> 0 | F17: {=INDEX($B$33:$B$156,O17)} -> 0 | G17: {=INDEX($C$33:$C$156,O17)} -> 0 | H17: {=MAX(IF($AC$33:$AC$156=$B17,$AA$33:$AA$156,""))} -> 0 | I17: {=INDEX($B$33:$B$156,Q17)} -> 0 | J17: {=INDEX($C$33:$C$156,Q17)} -> 0 | K17: {=MIN(IF($AC$33:$AC$156=$B17,$AB$33:$AB$156,""))} -> 0 | M17: {=MATCH(MAX(IF($AC$33:$AC$156=$B17,$Z$33:$Z$156,"")),$Z$33:$Z$156,0)} -> 121 | N17: {=INDEX($AC$33:$AC$156,M17)} -> 0 | O17: {=MATCH(MAX(IF($AC$33:$AC$156=$B17,$AA$33:$AA$156,"")),$AA$33:$AA$156,0)} -> 121 | P17: {=INDEX($AC$33:$AC$156,O17)} -> 0 | Q17: {=MATCH(MIN(IF($AC$33:$AC$156=$B17,$AB$33:$AB$156,"")),$AB$33:$AB$156,0)} -> 121 | R17: {=INDEX($AC$33:$AC$156,Q17)} -> 0 | S17: =IF($B17=N17,"OK","NG") -> OK | T17: =IF($B17=P17,"OK","NG") -> OK | U17: =IF($B17=R17,"OK","NG") -> OK | AC17: YR | AD17: X22-Y3/Y6 | AE17: =SUM(AV16:AV19)*-1 -> 113.2 | AF17: =SUM($BA$19:$BA$22) -> 6555 | AG17: =SUM(AW16:AW19) -> 3275.7 | AH17: =AE17+0.1*0.9*(AF17-AG17) -> 408.337 | AJ17: XR | AK17: Y1 | AL17: =ABS(SUMIFS(柱脚応力!$I:$I,柱脚応力!$C:$C,"x2?",柱脚応力!$B:$B,AK17)) -> 1036.8 | AM17: =SUMIFS($E$33:$E$152,$C$33:$C$152,"x2?",$B$33:$B$152,AK17) -> 3983.4 | AN17: =SUMIFS(柱脚応力!$Q:$Q, 柱脚応力!$C:$C,"x2?",柱脚応力!$B:$B,AK17) -> 1515.6 | AO17: =AL17+0.1*0.9*(AM17-AN17) -> 1258.902 | AQ17: y4 | AR17: x22 | AS17: 2.3 | AT17: -2.2 | AU17: 18.3 | AV17: -18 | AW17: 895.1 | AY17: Y1 | AZ17: x22 | BA17: =$E$44 -> 1523 | BD17: AXL2 | BE17: X2 | BF17: 280 | BG17: 210 | BH17: 210 | BI17: 210 | BJ17: 210 | BK17: 210 | BL17: 210 | BM17: 210 | BN17: 210 | BO17: 280
C18: {=INDEX($B$33:$B$156,M18)} -> 0 | D18: {=INDEX($C$33:$C$156,M18)} -> 0 | E18: {=MAX(IF($AC$33:$AC$156=$B18,$Z$33:$Z$156,""))} -> 0 | F18: {=INDEX($B$33:$B$156,O18)} -> 0 | G18: {=INDEX($C$33:$C$156,O18)} -> 0 | H18: {=MAX(IF($AC$33:$AC$156=$B18,$AA$33:$AA$156,""))} -> 0 | I18: {=INDEX($B$33:$B$156,Q18)} -> 0 | J18: {=INDEX($C$33:$C$156,Q18)} -> 0 | K18: {=MIN(IF($AC$33:$AC$156=$B18,$AB$33:$AB$156,""))} -> 0 | M18: {=MATCH(MAX(IF($AC$33:$AC$156=$B18,$Z$33:$Z$156,"")),$Z$33:$Z$156,0)} -> 121 | N18: {=INDEX($AC$33:$AC$156,M18)} -> 0 | O18: {=MATCH(MAX(IF($AC$33:$AC$156=$B18,$AA$33:$AA$156,"")),$AA$33:$AA$156,0)} -> 121 | P18: {=INDEX($AC$33:$AC$156,O18)} -> 0 | Q18: {=MATCH(MIN(IF($AC$33:$AC$156=$B18,$AB$33:$AB$156,"")),$AB$33:$AB$156,0)} -> 121 | R18: {=INDEX($AC$33:$AC$156,Q18)} -> 0 | S18: =IF($B18=N18,"OK","NG") -> OK | T18: =IF($B18=P18,"OK","NG") -> OK | U18: =IF($B18=R18,"OK","NG") -> OK | X18: XL | Y18: XR | Z18: YL | AA18: YR | AB18: 決定 | AC18: YR | AD18: X22-Y7/Y10 | AE18: =SUM(AV20)*-1 -> 744.3 | AF18: =SUM($BA$23:$BA$26) -> 7178.9 | AG18: =SUM(AW20) -> 401.9 | AH18: =AE18+0.1*0.9*(AF18-AG18) -> 1354.23 | AJ18: XR | AK18: Y2 | AL18: =ABS(SUMIFS(柱脚応力!$I:$I,柱脚応力!$C:$C,"x2?",柱脚応力!$B:$B,AK18)) -> 94.8 | AM18: =SUMIFS($E$33:$E$152,$C$33:$C$152,"x2?",$B$33:$B$152,AK18) -> 5546.4 | AN18: =SUMIFS(柱脚応力!$Q:$Q, 柱脚応力!$C:$C,"x2?",柱脚応力!$B:$B,AK18) -> 2568.2 | AO18: =AL18+0.1*0.9*(AM18-AN18) -> 362.838 | AQ18: y5 | AR18: x22 | AS18: 2.9 | AT18: -2.8 | AU18: 28.7 | AV18: -26.7 | AW18: 895.1 | AY18: Y2 | AZ18: x22 | BA18: =$E$56 -> 2087 | BD18: AXL2 | BE18: X1 | BF18: 280 | BG18: 280 | BH18: 280 | BI18: 280 | BJ18: 280 | BK18: 280 | BL18: 280 | BM18: 280 | BN18: 280 | BO18: 280
C19: {=INDEX($B$33:$B$156,M19)} -> 0 | D19: {=INDEX($C$33:$C$156,M19)} -> 0 | E19: {=MAX(IF($AC$33:$AC$156=$B19,$Z$33:$Z$156,""))} -> 0 | F19: {=INDEX($B$33:$B$156,O19)} -> 0 | G19: {=INDEX($C$33:$C$156,O19)} -> 0 | H19: {=MAX(IF($AC$33:$AC$156=$B19,$AA$33:$AA$156,""))} -> 0 | I19: {=INDEX($B$33:$B$156,Q19)} -> 0 | J19: {=INDEX($C$33:$C$156,Q19)} -> 0 | K19: {=MIN(IF($AC$33:$AC$156=$B19,$AB$33:$AB$156,""))} -> 0 | M19: {=MATCH(MAX(IF($AC$33:$AC$156=$B19,$Z$33:$Z$156,"")),$Z$33:$Z$156,0)} -> 121 | N19: {=INDEX($AC$33:$AC$156,M19)} -> 0 | O19: {=MATCH(MAX(IF($AC$33:$AC$156=$B19,$AA$33:$AA$156,"")),$AA$33:$AA$156,0)} -> 121 | P19: {=INDEX($AC$33:$AC$156,O19)} -> 0 | Q19: {=MATCH(MIN(IF($AC$33:$AC$156=$B19,$AB$33:$AB$156,"")),$AB$33:$AB$156,0)} -> 121 | R19: {=INDEX($AC$33:$AC$156,Q19)} -> 0 | S19: =IF($B19=N19,"OK","NG") -> OK | T19: =IF($B19=P19,"OK","NG") -> OK | U19: =IF($B19=R19,"OK","NG") -> OK | W19: 本体 | X19: =Z13 -> 39854.802 | Y19: =Z14 -> 39825.002 | Z19: =Z15 -> 39718.902 | AA19: =Z16 -> 39742.302 | AB19: 41000 | AJ19: XR | AK19: Y3 | AL19: =ABS(SUMIFS(柱脚応力!$I:$I,柱脚応力!$C:$C,"x2?",柱脚応力!$B:$B,AK19)) -> 91.7 | AM19: =SUMIFS($E$33:$E$152,$C$33:$C$152,"x2?",$B$33:$B$152,AK19) -> 4048.5 | AN19: =SUMIFS(柱脚応力!$Q:$Q, 柱脚応力!$C:$C,"x2?",柱脚応力!$B:$B,AK19) -> 2059.9 | AO19: =AL19+0.1*0.9*(AM19-AN19) -> 270.674 | AQ19: y6 | AR19: x22 | AS19: 5.9 | AT19: -512.9 | AU19: 738.6 | AV19: -52.1 | AW19: 783.1 | AY19: Y3 | AZ19: x22 | BA19: =$E$68 -> 1460.1
C20: {=INDEX($B$33:$B$156,M20)} -> 0 | D20: {=INDEX($C$33:$C$156,M20)} -> 0 | E20: {=MAX(IF($AC$33:$AC$156=$B20,$Z$33:$Z$156,""))} -> 0 | F20: {=INDEX($B$33:$B$156,O20)} -> 0 | G20: {=INDEX($C$33:$C$156,O20)} -> 0 | H20: {=MAX(IF($AC$33:$AC$156=$B20,$AA$33:$AA$156,""))} -> 0 | I20: {=INDEX($B$33:$B$156,Q20)} -> 0 | J20: {=INDEX($C$33:$C$156,Q20)} -> 0 | K20: {=MIN(IF($AC$33:$AC$156=$B20,$AB$33:$AB$156,""))} -> 0 | M20: {=MATCH(MAX(IF($AC$33:$AC$156=$B20,$Z$33:$Z$156,"")),$Z$33:$Z$156,0)} -> 121 | N20: {=INDEX($AC$33:$AC$156,M20)} -> 0 | O20: {=MATCH(MAX(IF($AC$33:$AC$156=$B20,$AA$33:$AA$156,"")),$AA$33:$AA$156,0)} -> 121 | P20: {=INDEX($AC$33:$AC$156,O20)} -> 0 | Q20: {=MATCH(MIN(IF($AC$33:$AC$156=$B20,$AB$33:$AB$156,"")),$AB$33:$AB$156,0)} -> 121 | R20: {=INDEX($AC$33:$AC$156,Q20)} -> 0 | S20: =IF($B20=N20,"OK","NG") -> OK | T20: =IF($B20=P20,"OK","NG") -> OK | U20: =IF($B20=R20,"OK","NG") -> OK | W20: a | X20: =AO7+AO8 -> 1577.64 | Y20: =AO17+AO18 -> 1621.74 | AB20: 1500 | AJ20: XR | AK20: Y4 | AL20: =ABS(SUMIFS(柱脚応力!$I:$I,柱脚応力!$C:$C,"x2?",柱脚応力!$B:$B,AK20)) -> 4.4 | AM20: =SUMIFS($E$33:$E$152,$C$33:$C$152,"x2?",$B$33:$B$152,AK20) -> 3463.8 | AN20: =SUMIFS(柱脚応力!$Q:$Q, 柱脚応力!$C:$C,"x2?",柱脚応力!$B:$B,AK20) -> 1793.6 | AO20: =AL20+0.1*0.9*(AM20-AN20) -> 154.718 | AQ20: y7 | AR20: x22 | AS20: 6.2 | AT20: -30.8 | AU20: 34.3 | AV20: -744.3 | AW20: 401.9 | AY20: Y4 | AZ20: x22 | BA20: =$E$80 -> 1732.1
C21: {=INDEX($B$33:$B$156,M21)} -> 0 | D21: {=INDEX($C$33:$C$156,M21)} -> 0 | E21: {=MAX(IF($AC$33:$AC$156=$B21,$Z$33:$Z$156,""))} -> 0 | F21: {=INDEX($B$33:$B$156,O21)} -> 0 | G21: {=INDEX($C$33:$C$156,O21)} -> 0 | H21: {=MAX(IF($AC$33:$AC$156=$B21,$AA$33:$AA$156,""))} -> 0 | I21: {=INDEX($B$33:$B$156,Q21)} -> 0 | J21: {=INDEX($C$33:$C$156,Q21)} -> 0 | K21: {=MAX(IF($AC$33:$AC$156=B21,$AB$33:$AB$156,""))} -> 0 | M21: {=MATCH(MAX(IF($AC$33:$AC$156=$B21,$Z$33:$Z$156,"")),$Z$33:$Z$156,0)} -> 121 | N21: {=INDEX($AC$33:$AC$156,M21)} -> 0 | O21: {=MATCH(MAX(IF($AC$33:$AC$156=$B21,$AA$33:$AA$156,"")),$AA$33:$AA$156,0)} -> 121 | P21: {=INDEX($AC$33:$AC$156,O21)} -> 0 | Q21: {=MATCH(MIN(IF($AC$33:$AC$156=$B21,$AB$33:$AB$156,"")),$AB$33:$AB$156,0)} -> 121 | R21: {=INDEX($AC$33:$AC$156,Q21)} -> 0 | S21: =IF($B21=N21,"OK","NG") -> OK | T21: =IF($B21=P21,"OK","NG") -> OK | U21: =IF($B21=R21,"OK","NG") -> OK | W21: b | X21: =AO9 -> 272.774 | Y21: =AO19 -> 270.674 | AB21: 300 | AC21: Qall | AD21: 総せん断力 | AJ21: XR | AK21: Y5 | AL21: =ABS(SUMIFS(柱脚応力!$I:$I,柱脚応力!$C:$C,"x2?",柱脚応力!$B:$B,AK21)) -> 5.6 | AM21: =SUMIFS($E$33:$E$152,$C$33:$C$152,"x2?",$B$33:$B$152,AK21) -> 3472.2 | AN21: =SUMIFS(柱脚応力!$Q:$Q, 柱脚応力!$C:$C,"x2?",柱脚応力!$B:$B,AK21) -> 1788.2 | AO21: =AL21+0.1*0.9*(AM21-AN21) -> 157.16 | AY21: Y5 | AZ21: x22 | BA21: =$E$92 -> 1735.5
C22: {=INDEX($B$33:$B$156,M22)} -> 0 | D22: {=INDEX($C$33:$C$156,M22)} -> 0 | E22: {=MAX(IF($AC$33:$AC$156=$B22,$Z$33:$Z$156,""))} -> 0 | F22: {=INDEX($B$33:$B$156,O22)} -> 0 | G22: {=INDEX($C$33:$C$156,O22)} -> 0 | H22: {=MAX(IF($AC$33:$AC$156=$B22,$AA$33:$AA$156,""))} -> 0 | I22: {=INDEX($B$33:$B$156,Q22)} -> 0 | J22: {=INDEX($C$33:$C$156,Q22)} -> 0 | K22: {=MAX(IF($AC$33:$AC$156=B22,$AB$33:$AB$156,""))} -> 0 | M22: {=MATCH(MAX(IF($AC$33:$AC$156=$B22,$Z$33:$Z$156,"")),$Z$33:$Z$156,0)} -> 121 | N22: {=INDEX($AC$33:$AC$156,M22)} -> 0 | O22: {=MATCH(MAX(IF($AC$33:$AC$156=$B22,$AA$33:$AA$156,"")),$AA$33:$AA$156,0)} -> 121 | P22: {=INDEX($AC$33:$AC$156,O22)} -> 0 | Q22: {=MATCH(MIN(IF($AC$33:$AC$156=$B22,$AB$33:$AB$156,"")),$AB$33:$AB$156,0)} -> 121 | R22: {=INDEX($AC$33:$AC$156,Q22)} -> 0 | S22: =IF($B22=N22,"OK","NG") -> OK | T22: =IF($B22=P22,"OK","NG") -> OK | U22: =IF($B22=R22,"OK","NG") -> OK | W22: c | X22: =AO10 -> 154.918 | Y22: =AO20 -> 154.718 | AB22: 200 | AC22: Qc | AD22: 柱脚せん断力 | AJ22: XR | AK22: Y6 | AL22: =ABS(SUMIFS(柱脚応力!$I:$I,柱脚応力!$C:$C,"x2?",柱脚応力!$B:$B,AK22)) -> 518.7 | AM22: =SUMIFS($E$33:$E$152,$C$33:$C$152,"x2?",$B$33:$B$152,AK22) -> 3240.8 | AN22: =SUMIFS(柱脚応力!$Q:$Q, 柱脚応力!$C:$C,"x2?",柱脚応力!$B:$B,AK22) -> 1564.9 | AO22: =AL22+0.1*0.9*(AM22-AN22) -> 669.531 | AY22: Y6 | AZ22: x22 | BA22: =$E$104 -> 1627.3
C23: {=INDEX($B$33:$B$156,M23)} -> 0 | D23: {=INDEX($C$33:$C$156,M23)} -> 0 | E23: {=MAX(IF($AC$33:$AC$156=$B23,$Z$33:$Z$156,""))} -> 0 | F23: {=INDEX($B$33:$B$156,O23)} -> 0 | G23: {=INDEX($C$33:$C$156,O23)} -> 0 | H23: {=MAX(IF($AC$33:$AC$156=$B23,$AA$33:$AA$156,""))} -> 0 | I23: {=INDEX($B$33:$B$156,Q23)} -> 0 | J23: {=INDEX($C$33:$C$156,Q23)} -> 0 | K23: {=MAX(IF($AC$33:$AC$156=B23,$AB$33:$AB$156,""))} -> 0 | M23: {=MATCH(MAX(IF($AC$33:$AC$156=$B23,$Z$33:$Z$156,"")),$Z$33:$Z$156,0)} -> 121 | N23: {=INDEX($AC$33:$AC$156,M23)} -> 0 | O23: {=MATCH(MAX(IF($AC$33:$AC$156=$B23,$AA$33:$AA$156,"")),$AA$33:$AA$156,0)} -> 121 | P23: {=INDEX($AC$33:$AC$156,O23)} -> 0 | Q23: {=MATCH(MIN(IF($AC$33:$AC$156=$B23,$AB$33:$AB$156,"")),$AB$33:$AB$156,0)} -> 121 | R23: {=INDEX($AC$33:$AC$156,Q23)} -> 0 | S23: =IF($B23=N23,"OK","NG") -> OK | T23: =IF($B23=P23,"OK","NG") -> OK | U23: =IF($B23=R23,"OK","NG") -> OK | W23: d | X23: =AO11 -> 157.36 | Y23: =AO21 -> 157.16 | AB23: 200 | AC23: Qm | AD23: 本体棟せん断力 | AJ23: XR | AK23: Y7 | AL23: =ABS(SUMIFS(柱脚応力!$I:$I,柱脚応力!$C:$C,"x2?",柱脚応力!$B:$B,AK23)) -> 36.9 | AM23: =SUMIFS($E$33:$E$152,$C$33:$C$152,"x2?",$B$33:$B$152,AK23) -> 4339.6 | AN23: =SUMIFS(柱脚応力!$Q:$Q, 柱脚応力!$C:$C,"x2?",柱脚応力!$B:$B,AK23) -> 801.9 | AO23: =AL23+0.1*0.9*(AM23-AN23) -> 355.293 | AY23: Y7 | AZ23: x22 | BA23: =$E$116 -> 1924.9
C24: {=INDEX($B$33:$B$156,M24)} -> 0 | D24: {=INDEX($C$33:$C$156,M24)} -> 0 | E24: {=MAX(IF($AC$33:$AC$156=$B24,$Z$33:$Z$156,""))} -> 0 | F24: {=INDEX($B$33:$B$156,O24)} -> 0 | G24: {=INDEX($C$33:$C$156,O24)} -> 0 | H24: {=MAX(IF($AC$33:$AC$156=$B24,$AA$33:$AA$156,""))} -> 0 | I24: {=INDEX($B$33:$B$156,Q24)} -> 0 | J24: {=INDEX($C$33:$C$156,Q24)} -> 0 | K24: {=MAX(IF($AC$33:$AC$156=B24,$AB$33:$AB$156,""))} -> 0 | M24: {=MATCH(MAX(IF($AC$33:$AC$156=$B24,$Z$33:$Z$156,"")),$Z$33:$Z$156,0)} -> 121 | N24: {=INDEX($AC$33:$AC$156,M24)} -> 0 | O24: {=MATCH(MAX(IF($AC$33:$AC$156=$B24,$AA$33:$AA$156,"")),$AA$33:$AA$156,0)} -> 121 | P24: {=INDEX($AC$33:$AC$156,O24)} -> 0 | Q24: {=MATCH(MIN(IF($AC$33:$AC$156=$B24,$AB$33:$AB$156,"")),$AB$33:$AB$156,0)} -> 121 | R24: {=INDEX($AC$33:$AC$156,Q24)} -> 0 | S24: =IF($B24=N24,"OK","NG") -> OK | T24: =IF($B24=P24,"OK","NG") -> OK | U24: =IF($B24=R24,"OK","NG") -> OK | W24: e | X24: =AO12 -> 680.331 | Y24: =AO22 -> 669.531 | AB24: 700 | AC24: Qs | AD24: スロープ棟せん断力 | AJ24: XR | AK24: Y8 | AL24: =ABS(SUMIFS(柱脚応力!$I:$I,柱脚応力!$C:$C,"x2?",柱脚応力!$B:$B,AK24)) -> 0 | AM24: =SUMIFS($E$33:$E$152,$C$33:$C$152,"x2?",$B$33:$B$152,AK24) -> 4375.9 | AN24: =SUMIFS(柱脚応力!$Q:$Q, 柱脚応力!$C:$C,"x2?",柱脚応力!$B:$B,AK24) -> 0 | AO24: =AL24+0.1*0.9*(AM24-AN24) -> 393.831 | AY24: Y8 | AZ24: x22 | BA24: =$E$128 -> 2186.8
C25: {=INDEX($B$33:$B$156,M25)} -> 0 | D25: {=INDEX($C$33:$C$156,M25)} -> 0 | E25: {=MAX(IF($AC$33:$AC$156=$B25,$Z$33:$Z$156,""))} -> 0 | F25: {=INDEX($B$33:$B$156,O25)} -> 0 | G25: {=INDEX($C$33:$C$156,O25)} -> 0 | H25: {=MAX(IF($AC$33:$AC$156=$B25,$AA$33:$AA$156,""))} -> 0 | I25: {=INDEX($B$33:$B$156,Q25)} -> 0 | J25: {=INDEX($C$33:$C$156,Q25)} -> 0 | K25: {=MAX(IF($AC$33:$AC$156=B25,$AB$33:$AB$156,""))} -> 0 | M25: {=MATCH(MAX(IF($AC$33:$AC$156=$B25,$Z$33:$Z$156,"")),$Z$33:$Z$156,0)} -> 121 | N25: {=INDEX($AC$33:$AC$156,M25)} -> 0 | O25: {=MATCH(MAX(IF($AC$33:$AC$156=$B25,$AA$33:$AA$156,"")),$AA$33:$AA$156,0)} -> 121 | P25: {=INDEX($AC$33:$AC$156,O25)} -> 0 | Q25: {=MATCH(MIN(IF($AC$33:$AC$156=$B25,$AB$33:$AB$156,"")),$AB$33:$AB$156,0)} -> 121 | R25: {=INDEX($AC$33:$AC$156,Q25)} -> 0 | S25: =IF($B25=N25,"OK","NG") -> OK | T25: =IF($B25=P25,"OK","NG") -> OK | U25: =IF($B25=R25,"OK","NG") -> OK | W25: f | X25: =SUM(AO13:AO16) -> 1302.175 | Y25: =SUM(AO23:AO26) -> 1301.175 | AB25: 1400 | AC25: N | AD25: 支点反力 | AF25: 基礎を梁に見立ててせん断力の検討に、 | AJ25: XR | AK25: Y9 | AL25: =ABS(SUMIFS(柱脚応力!$I:$I,柱脚応力!$C:$C,"x2?",柱脚応力!$B:$B,AK25)) -> 0 | AM25: =SUMIFS($E$33:$E$152,$C$33:$C$152,"x2?",$B$33:$B$152,AK25) -> 4226.9 | AN25: =SUMIFS(柱脚応力!$Q:$Q, 柱脚応力!$C:$C,"x2?",柱脚応力!$B:$B,AK25) -> 0 | AO25: =AL25+0.1*0.9*(AM25-AN25) -> 380.421 | AY25: Y9 | AZ25: x22 | BA25: =$E$140 -> 2113.7
C26: {=INDEX($B$33:$B$156,M26)} -> 0 | D26: {=INDEX($C$33:$C$156,M26)} -> 0 | E26: {=MAX(IF($AC$33:$AC$156=$B26,$Z$33:$Z$156,""))} -> 0 | F26: {=INDEX($B$33:$B$156,O26)} -> 0 | G26: {=INDEX($C$33:$C$156,O26)} -> 0 | H26: {=MAX(IF($AC$33:$AC$156=$B26,$AA$33:$AA$156,""))} -> 0 | I26: {=INDEX($B$33:$B$156,Q26)} -> 0 | J26: {=INDEX($C$33:$C$156,Q26)} -> 0 | K26: {=MAX(IF($AC$33:$AC$156=B26,$AB$33:$AB$156,""))} -> 0 | M26: {=MATCH(MAX(IF($AC$33:$AC$156=$B26,$Z$33:$Z$156,"")),$Z$33:$Z$156,0)} -> 121 | N26: {=INDEX($AC$33:$AC$156,M26)} -> 0 | O26: {=MATCH(MAX(IF($AC$33:$AC$156=$B26,$AA$33:$AA$156,"")),$AA$33:$AA$156,0)} -> 121 | P26: {=INDEX($AC$33:$AC$156,O26)} -> 0 | Q26: {=MATCH(MIN(IF($AC$33:$AC$156=$B26,$AB$33:$AB$156,"")),$AB$33:$AB$156,0)} -> 121 | R26: {=INDEX($AC$33:$AC$156,Q26)} -> 0 | S26: =IF($B26=N26,"OK","NG") -> OK | T26: =IF($B26=P26,"OK","NG") -> OK | U26: =IF($B26=R26,"OK","NG") -> OK | W26: A | Z26: =AH7+AH10 -> 1375.24 | AA26: =AH13+AH16 -> 1333.04 | AB26: 1300 | AC26: Nc | AD26: 柱脚軸力 | AF26: αを考慮する場合は、 | AJ26: XR | AK26: Y10 | AL26: =ABS(SUMIFS(柱脚応力!$I:$I,柱脚応力!$C:$C,"x2?",柱脚応力!$B:$B,AK26)) -> 0 | AM26: =SUMIFS($E$33:$E$152,$C$33:$C$152,"x2?",$B$33:$B$152,AK26) -> 1907 | AN26: =SUMIFS(柱脚応力!$Q:$Q, 柱脚応力!$C:$C,"x2?",柱脚応力!$B:$B,AK26) -> 0 | AO26: =AL26+0.1*0.9*(AM26-AN26) -> 171.63 | AY26: Y10 | AZ26: x22 | BA26: =$E$152 -> 953.5
W27: B | Z27: =AH8 -> 465.146 | AA27: =AH14 -> 464.746 | AB27: 750 | AF27: 短期設計用せん断力の地震時せん断力を
W28: C | Z28: =AH11 -> 1097.637 | AA28: =AH17 -> 408.337 | AB28: 1200 | AF28: 1.5倍する必要がある。
B29: 地震時の水平力kNとしてください | G29: 建物水平力(kN) | H29: 基礎(kN) | I29: フーチング | J29: 44000 | W29: D | Z29: =AH9+AH12 -> 1343.075 | AA29: =AH15+AH18 -> 2051.575 | AB29: 2100
B30: 支点応力まとめ | G30: 23763 | H30: 186711 | I30: =SUM(BF7:BO18) -> 28280 | J30: =G30+0.1*(H30+I30)*0.9 -> 43112.19 | K30: →46000kN | L30: で計算ください | AA30: ↓地震時の1.5倍+長期荷重した値です。これは単純にフーチング計算用です
B31: 固定荷重+積載荷重 | F31: 雪荷重(長期にするときは0.7倍) | J31: X方向地震左 | N31: X方向地震右 | R31: Y方向地震左 | V31: Y方向地震右 | Z31: 長期 | AA31: 支持力max | AB31: 支持力min | AC31: フーチング | AD31: 前回との誤差
B32: 通 | C32: 軸 | D32: 荷重 | E32: 反力(kN) | F32: 通 | G32: 軸 | H32: 荷重 | I32: 反力(kN) | J32: 通 | K32: 軸 | L32: 荷重 | M32: 反力(kN) | N32: 通 | O32: 軸 | P32: 荷重 | Q32: 反力(kN) | R32: 通 | S32: 軸 | T32: 荷重 | U32: 反力(kN) | V32: 通 | W32: 軸 | X32: 荷重 | Y32: 反力(kN) | AD32: 通 | AE32: 長期 | AF32: X方向地震左 | AG32: X方向地震右 | AH32: Y方向地震左 | AI32: Y方向地震右
A33: 固定＋積載には | B33: y1 | C33: x1 | D33: v | E33: 1562 | F33: y1 | G33: x1 | H33: s | I33: 25.7 | J33: y1 | K33: x1 | L33: exl | M33: -938.9 | N33: y1 | O33: x1 | P33: exr | Q33: 905.4 | R33: y1 | S33: x1 | T33: eyl | U33: -147 | V33: y1 | W33: x1 | X33: eyr | Y33: 89.1 | Z33: =E33 -> 1562 | AA33: =E33+MAX(M33,Q33,U33,Y33)*1.5 -> 2920.1 | AB33: =E33+MIN(M33,Q33,U33,Y33) -> 623.1 | AC33: F30 | AD33: =V33&"-"&W33 -> y1-x1 | AE33: =E33-E160 -> 21.5 | AF33: =M33-M160 -> -237.3 | AG33: =ABS(ABS(Q33)-ABS(Q160)) -> 232 | AH33: =ABS(ABS(U33)-ABS(U160)) -> 19 | AI33: =ABS(ABS(Y33)-ABS(Y160)) -> 18.3 | AJ33: =BB4 -> 0 | AK33: 0 | AL33: =Z33+AK33 -> 1562 | AM33: ="RST5 "& B33 &" " & C33 & " 100000000-100000000-1.0-0.00001-100000000-100000000 " &AL33&"-"&AL33&"-1.0-0.000000001" -> RST5 y1 x1 100000000-100000000-1.0-0.00001-100000000-100000000 1562-1562-1.0-0.000000001
A34: 基礎重量wfは入れています。 | B34: y1 | C34: x2 | D34: v | E34: 2879.3 | F34: y1 | G34: x2 | H34: s | I34: 57.2 | J34: y1 | K34: x2 | L34: exl | M34: 9.3 | N34: y1 | O34: x2 | P34: exr | Q34: 16.7 | R34: y1 | S34: x2 | T34: eyl | U34: -246 | V34: y1 | W34: x2 | X34: eyr | Y34: 340.4 | Z34: =E34 -> 2879.3 | AA34: =E34+MAX(M34,Q34,U34,Y34)*1.5 -> 3389.9 | AB34: =E34+MIN(M34,Q34,U34,Y34) -> 2633.3 | AC34: F21 | AD34: =V34&"-"&W34 -> y1-x2 | AE34: =E34-E161 -> -9.1 | AF34: =M34-M161 -> 112.6 | AG34: =ABS(ABS(Q34)-ABS(Q161)) -> 95.6 | AH34: =ABS(ABS(U34)-ABS(U161)) -> 22.4 | AI34: =ABS(ABS(Y34)-ABS(Y161)) -> 100.5 | AJ34: =BB5 -> 0 | AK34: 0 | AL34: =Z34+AK34 -> 2879.3 | AM34: ="RST5 "& B34 &" " & C34 & " 100000000-100000000-1.0-0.00001-100000000-100000000 " &AL34&"-"&AL34&"-1.0-0.000000001" -> RST5 y1 x2 100000000-100000000-1.0-0.00001-100000000-100000000 2879.3-2879.3-1.0-0.000000001
B35: y1 | C35: x3 | D35: v | E35: 3084.1 | F35: y1 | G35: x3 | H35: s | I35: 57.2 | J35: y1 | K35: x3 | L35: exl | M35: -336.2 | N35: y1 | O35: x3 | P35: exr | Q35: 304.4 | R35: y1 | S35: x3 | T35: eyl | U35: -635.5 | V35: y1 | W35: x3 | X35: eyr | Y35: 582.2 | Z35: =E35 -> 3084.1 | AA35: =E35+MAX(M35,Q35,U35,Y35)*1.5 -> 3957.4 | AB35: =E35+MIN(M35,Q35,U35,Y35) -> 2448.6 | AC35: F21 | AD35: =V35&"-"&W35 -> y1-x3 | AE35: =E35-E162 -> 341.8 | AF35: =M35-M162 -> 4.8 | AG35: =ABS(ABS(Q35)-ABS(Q162)) -> 9.2 | AH35: =ABS(ABS(U35)-ABS(U162)) -> 2.7 | AI35: =ABS(ABS(Y35)-ABS(Y162)) -> 260.3 | AJ35: =BB6 -> 0 | AK35: 0 | AL35: =Z35+AK35 -> 3084.1 | AM35: ="RST5 "& B35 &" " & C35 & " 100000000-100000000-1.0-0.00001-100000000-100000000 " &AL35&"-"&AL35&"-1.0-0.000000001" -> RST5 y1 x3 100000000-100000000-1.0-0.00001-100000000-100000000 3084.1-3084.1-1.0-0.000000001
B36: y1 | C36: x4 | D36: v | E36: 3025.1 | F36: y1 | G36: x4 | H36: s | I36: 50.6 | J36: y1 | K36: x4 | L36: exl | M36: 304.8 | N36: y1 | O36: x4 | P36: exr | Q36: -284.2 | R36: y1 | S36: x4 | T36: eyl | U36: -1204.7 | V36: y1 | W36: x4 | X36: eyr | Y36: 1091.9 | Z36: =E36 -> 3025.1 | AA36: =E36+MAX(M36,Q36,U36,Y36)*1.5 -> 4662.95 | AB36: =E36+MIN(M36,Q36,U36,Y36) -> 1820.4 | AC36: F20 | AD36: =V36&"-"&W36 -> y1-x4 | AE36: =E36-E163 -> -119.9 | AF36: =M36-M163 -> 249.1 | AG36: =ABS(ABS(Q36)-ABS(Q163)) -> 247.7 | AH36: =ABS(ABS(U36)-ABS(U163)) -> 27.2 | AI36: =ABS(ABS(Y36)-ABS(Y163)) -> 64.2 | AJ36: =BB7 -> 0 | AK36: 0 | AL36: =Z36+AK36 -> 3025.1 | AM36: ="RST5 "& B36 &" " & C36 & " 100000000-100000000-1.0-0.00001-100000000-100000000 " &AL36&"-"&AL36&"-1.0-0.000000001" -> RST5 y1 x4 100000000-100000000-1.0-0.00001-100000000-100000000 3025.1-3025.1-1.0-0.000000001
B37: y1 | C37: x5 | D37: v | E37: 2761.4 | F37: y1 | G37: x5 | H37: s | I37: 58.5 | J37: y1 | K37: x5 | L37: exl | M37: -10.8 | N37: y1 | O37: x5 | P37: exr | Q37: -2.8 | R37: y1 | S37: x5 | T37: eyl | U37: -288.4 | V37: y1 | W37: x5 | X37: eyr | Y37: 368.4 | Z37: =E37 -> 2761.4 | AA37: =E37+MAX(M37,Q37,U37,Y37)*1.5 -> 3314 | AB37: =E37+MIN(M37,Q37,U37,Y37) -> 2473 | AC37: F21 | AD37: =V37&"-"&W37 -> y1-x5 | AE37: =E37-E164 -> -363 | AF37: =M37-M164 -> -5.7 | AG37: =ABS(ABS(Q37)-ABS(Q164)) -> 12.7 | AH37: =ABS(ABS(U37)-ABS(U164)) -> 19.4 | AI37: =ABS(ABS(Y37)-ABS(Y164)) -> 43 | AJ37: =BB8 -> 0 | AK37: 0 | AL37: =Z37+AK37 -> 2761.4 | AM37: ="RST5 "& B37 &" " & C37 & " 100000000-100000000-1.0-0.00001-100000000-100000000 " &AL37&"-"&AL37&"-1.0-0.000000001" -> RST5 y1 x5 100000000-100000000-1.0-0.00001-100000000-100000000 2761.4-2761.4-1.0-0.000000001
B38: y1 | C38: x6 | D38: v | E38: 2783.8 | F38: y1 | G38: x6 | H38: s | I38: 58.6 | J38: y1 | K38: x6 | L38: exl | M38: -245.4 | N38: y1 | O38: x6 | P38: exr | Q38: 255 | R38: y1 | S38: x6 | T38: eyl | U38: -740.1 | V38: y1 | W38: x6 | X38: eyr | Y38: 309.8 | Z38: =E38 -> 2783.8 | AA38: =E38+MAX(M38,Q38,U38,Y38)*1.5 -> 3248.5 | AB38: =E38+MIN(M38,Q38,U38,Y38) -> 2043.7 | AC38: F21 | AD38: =V38&"-"&W38 -> y1-x6 | AE38: =E38-E165 -> 11.5 | AF38: =M38-M165 -> -260.1 | AG38: =ABS(ABS(Q38)-ABS(Q165)) -> 233.2 | AH38: =ABS(ABS(U38)-ABS(U165)) -> 60.2 | AI38: =ABS(ABS(Y38)-ABS(Y165)) -> 16.9 | AJ38: =BB9 -> 0 | AK38: 0 | AL38: =Z38+AK38 -> 2783.8 | AM38: ="RST5 "& B38 &" " & C38 & " 100000000-100000000-1.0-0.00001-100000000-100000000 " &AL38&"-"&AL38&"-1.0-0.000000001" -> RST5 y1 x6 100000000-100000000-1.0-0.00001-100000000-100000000 2783.8-2783.8-1.0-0.000000001
B39: y1 | C39: x7 | D39: v | E39: 2871.6 | F39: y1 | G39: x7 | H39: s | I39: 51.2 | J39: y1 | K39: x7 | L39: exl | M39: 309.9 | N39: y1 | O39: x7 | P39: exr | Q39: -315 | R39: y1 | S39: x7 | T39: eyl | U39: -1435.8 | V39: y1 | W39: x7 | X39: eyr | Y39: 1325.4 | Z39: =E39 -> 2871.6 | AA39: =E39+MAX(M39,Q39,U39,Y39)*1.5 -> 4859.7 | AB39: =E39+MIN(M39,Q39,U39,Y39) -> 1435.8 | AC39: F21 | AD39: =V39&"-"&W39 -> y1-x7 | AE39: =E39-E166 -> -5.9 | AF39: =M39-M166 -> 221.9 | AG39: =ABS(ABS(Q39)-ABS(Q166)) -> 229.8 | AH39: =ABS(ABS(U39)-ABS(U166)) -> 23.4 | AI39: =ABS(ABS(Y39)-ABS(Y166)) -> 133.6 | AJ39: =BB10 -> 0 | AK39: 0 | AL39: =Z39+AK39 -> 2871.6 | AM39: ="RST5 "& B39 &" " & C39 & " 100000000-100000000-1.0-0.00001-100000000-100000000 " &AL39&"-"&AL39&"-1.0-0.000000001" -> RST5 y1 x7 100000000-100000000-1.0-0.00001-100000000-100000000 2871.6-2871.6-1.0-0.000000001
B40: y1 | C40: x8 | D40: v | E40: 2610.7 | F40: y1 | G40: x8 | H40: s | I40: 52.7 | J40: y1 | K40: x8 | L40: exl | M40: 760.7 | N40: y1 | O40: x8 | P40: exr | Q40: -776.8 | R40: y1 | S40: x8 | T40: eyl | U40: -316.5 | V40: y1 | W40: x8 | X40: eyr | Y40: 358 | Z40: =E40 -> 2610.7 | AA40: =E40+MAX(M40,Q40,U40,Y40)*1.5 -> 3751.75 | AB40: =E40+MIN(M40,Q40,U40,Y40) -> 1833.9 | AC40: F21 | AD40: =V40&"-"&W40 -> y1-x8 | AE40: =E40-E167 -> 79.5 | AF40: =M40-M167 -> -128.5 | AG40: =ABS(ABS(Q40)-ABS(Q167)) -> 133.7 | AH40: =ABS(ABS(U40)-ABS(U167)) -> 22.7 | AI40: =ABS(ABS(Y40)-ABS(Y167)) -> 35.6 | AJ40: =BB11 -> 0 | AK40: 0 | AL40: =Z40+AK40 -> 2610.7 | AM40: ="RST5 "& B40 &" " & C40 & " 100000000-100000000-1.0-0.00001-100000000-100000000 " &AL40&"-"&AL40&"-1.0-0.000000001" -> RST5 y1 x8 100000000-100000000-1.0-0.00001-100000000-100000000 2610.7-2610.7-1.0-0.000000001
B41: y1 | C41: x9 | D41: v | E41: 2954.5 | F41: y1 | G41: x9 | H41: s | I41: 24.4 | J41: y1 | K41: x9 | L41: exl | M41: -50.8 | N41: y1 | O41: x9 | P41: exr | Q41: 20.2 | R41: y1 | S41: x9 | T41: eyl | U41: -343.7 | V41: y1 | W41: x9 | X41: eyr | Y41: 349.3 | Z41: =E41 -> 2954.5 | AA41: =E41+MAX(M41,Q41,U41,Y41)*1.5 -> 3478.45 | AB41: =E41+MIN(M41,Q41,U41,Y41) -> 2610.8 | AC41: F21 | AD41: =V41&"-"&W41 -> y1-x9 | AE41: =E41-E168 -> 215 | AF41: =M41-M168 -> -24.4 | AG41: =ABS(ABS(Q41)-ABS(Q168)) -> 14.4 | AH41: =ABS(ABS(U41)-ABS(U168)) -> 28.2 | AI41: =ABS(ABS(Y41)-ABS(Y168)) -> 26.6 | AJ41: =BB12 -> 0 | AK41: 0 | AL41: =Z41+AK41 -> 2954.5 | AM41: ="RST5 "& B41 &" " & C41 & " 100000000-100000000-1.0-0.00001-100000000-100000000 " &AL41&"-"&AL41&"-1.0-0.000000001" -> RST5 y1 x9 100000000-100000000-1.0-0.00001-100000000-100000000 2954.5-2954.5-1.0-0.000000001
B42: y1 | C42: x10 | D42: v | E42: 2887.6 | F42: y1 | G42: x10 | H42: s | I42: 0 | J42: y1 | K42: x10 | L42: exl | M42: 87.9 | N42: y1 | O42: x10 | P42: exr | Q42: -93.4 | R42: y1 | S42: x10 | T42: eyl | U42: -223 | V42: y1 | W42: x10 | X42: eyr | Y42: 227.9 | Z42: =E42 -> 2887.6 | AA42: =E42+MAX(M42,Q42,U42,Y42)*1.5 -> 3229.45 | AB42: =E42+MIN(M42,Q42,U42,Y42) -> 2664.6 | AC42: F20 | AD42: =V42&"-"&W42 -> y1-x10 | AE42: =E42-E169 -> 180.7 | AF42: =M42-M169 -> 30.3 | AG42: =ABS(ABS(Q42)-ABS(Q169)) -> 16.1 | AH42: =ABS(ABS(U42)-ABS(U169)) -> 9.9 | AI42: =ABS(ABS(Y42)-ABS(Y169)) -> 16.2 | AJ42: =BB13 -> 0 | AK42: 0 | AL42: =Z42+AK42 -> 2887.6 | AM42: ="RST5 "& B42 &" " & C42 & " 100000000-100000000-1.0-0.00001-100000000-100000000 " &AL42&"-"&AL42&"-1.0-0.000000001" -> RST5 y1 x10 100000000-100000000-1.0-0.00001-100000000-100000000 2887.6-2887.6-1.0-0.000000001
B43: y1 | C43: x21 | D43: v | E43: 2460.4 | F43: y1 | G43: x21 | H43: s | I43: -1.2 | J43: y1 | K43: x21 | L43: exl | M43: -741.5 | N43: y1 | O43: x21 | P43: exr | Q43: 748.1 | R43: y1 | S43: x21 | T43: eyl | U43: -781.1 | V43: y1 | W43: x21 | X43: eyr | Y43: 725.2 | Z43: =E43 -> 2460.4 | AA43: =E43+MAX(M43,Q43,U43,Y43)*1.5 -> 3582.55 | AB43: =E43+MIN(M43,Q43,U43,Y43) -> 1679.3 | AC43: F20 | AD43: =V43&"-"&W43 -> y1-x21 | AE43: =E43-E170 -> 148 | AF43: =M43-M170 -> -236.2 | AG43: =ABS(ABS(Q43)-ABS(Q170)) -> 215.3 | AH43: =ABS(ABS(U43)-ABS(U170)) -> 194.8 | AI43: =ABS(ABS(Y43)-ABS(Y170)) -> 186.5 | AJ43: =BB14 -> 0 | AK43: 0 | AL43: =Z43+AK43 -> 2460.4 | AM43: ="RST5 "& B43 &" " & C43 & " 100000000-100000000-1.0-0.00001-100000000-100000000 " &AL43&"-"&AL43&"-1.0-0.000000001" -> RST5 y1 x21 100000000-100000000-1.0-0.00001-100000000-100000000 2460.4-2460.4-1.0-0.000000001
B44: y1 | C44: x22 | D44: v | E44: 1523 | F44: y1 | G44: x22 | H44: s | I44: -0.1 | J44: y1 | K44: x22 | L44: exl | M44: 802.9 | N44: y1 | O44: x22 | P44: exr | Q44: -819.1 | R44: y1 | S44: x22 | T44: eyl | U44: -279.6 | V44: y1 | W44: x22 | X44: eyr | Y44: 311.2 | Z44: =E44 -> 1523 | AA44: =E44+MAX(M44,Q44,U44,Y44)*1.5 -> 2727.35 | AB44: =E44+MIN(M44,Q44,U44,Y44) -> 703.9 | AC44: F10 | AD44: =V44&"-"&W44 -> y1-x22 | AE44: =E44-E171 -> 481.7 | AF44: =M44-M171 -> 185.3 | AG44: =ABS(ABS(Q44)-ABS(Q171)) -> 192.4 | AH44: =ABS(ABS(U44)-ABS(U171)) -> 63 | AI44: =ABS(ABS(Y44)-ABS(Y171)) -> 65.6 | AJ44: =BB15 -> 0 | AK44: 0 | AL44: =Z44+AK44 -> 1523 | AM44: ="RST5 "& B44 &" " & C44 & " 100000000-100000000-1.0-0.00001-100000000-100000000 " &AL44&"-"&AL44&"-1.0-0.000000001" -> RST5 y1 x22 100000000-100000000-1.0-0.00001-100000000-100000000 1523-1523-1.0-0.000000001
B45: y2 | C45: x1 | D45: v | E45: 2613.6 | F45: y2 | G45: x1 | H45: s | I45: 51.7 | J45: y2 | K45: x1 | L45: exl | M45: -205.6 | N45: y2 | O45: x1 | P45: exr | Q45: 214.1 | R45: y2 | S45: x1 | T45: eyl | U45: -860.6 | V45: y2 | W45: x1 | X45: eyr | Y45: 895.7 | Z45: =E45 -> 2613.6 | AA45: =E45+MAX(M45,Q45,U45,Y45)*1.5 -> 3957.15 | AB45: =E45+MIN(M45,Q45,U45,Y45) -> 1753 | AC45: F21 | AD45: =V45&"-"&W45 -> y2-x1 | AE45: =E45-E172 -> 44.5 | AF45: =M45-M172 -> 11.2 | AG45: =ABS(ABS(Q45)-ABS(Q172)) -> 16.7 | AH45: =ABS(ABS(U45)-ABS(U172)) -> 19.5 | AI45: =ABS(ABS(Y45)-ABS(Y172)) -> 18.5 | AJ45: =BA4 -> 0 | AK45: 0 | AL45: =Z45+AK45 -> 2613.6 | AM45: ="RST5 "& B45 &" " & C45 & " 100000000-100000000-1.0-0.00001-100000000-100000000 " &AL45&"-"&AL45&"-1.0-0.000000001" -> RST5 y2 x1 100000000-100000000-1.0-0.00001-100000000-100000000 2613.6-2613.6-1.0-0.000000001
...

Sheet 柱脚応力
B1: Y方向 | C1: X方向 | D1: 柱符号 | E1: XL柱脚M(kNm) | F1: XL柱脚Q(kN) | G1: XL軸力(kN) | H1: XR柱脚M(kNm) | I1: XR柱脚Q(kN) | J1: XR軸力(kN) | K1: YL柱脚M(kNm) | L1: YL柱脚Q(kN) | M1: YL軸力(kN) | N1: YR柱脚M(kNm) | O1: YR柱脚Q(kN) | P1: YR軸力(kN) | Q1: 長期柱軸力
A2: =B2&"-"&C2 -> y1-x21 | B2: y1 | C2: x21 | D2: c10x | E2: 115.3 | F2: 949.6 | G2: -503.4 | H2: -135.8 | I2: -48.4 | J2: 509.4 | K2: 26.1 | L2: 870.6 | M2: -463.1 | N2: -33.5 | O2: -5 | P2: 421.3 | Q2: 1108.5
A3: =B3&"-"&C3 -> y2-x21 | B3: y2 | C3: x21 | D3: c10x | E3: 135.9 | F3: 49.6 | G3: 1.5 | H3: -134.4 | I3: -49.1 | J3: 15.8 | K3: 35.5 | L3: 5.4 | M3: 537.7 | N3: -27 | O3: -829 | P3: -522.7 | Q3: 1876.8
A4: =B4&"-"&C4 -> y3-x21 | B4: y3 | C4: x21 | D4: c10x | E4: 135.5 | F4: 49.6 | G4: -32.6 | H4: -132.7 | I4: -48.5 | J4: 28.7 | K4: 56.7 | L4: 18.1 | M4: -20.1 | N4: -59.5 | O4: -18.8 | P4: 23.6 | Q4: 1357.5
A5: =B5&"-"&C5 -> y4-x21 | B5: y4 | C5: x21 | D5: c11y | E5: 13.8 | F5: 2.3 | G5: -22.2 | H5: -13.5 | I5: -2.2 | J5: 20.9 | K5: 55.3 | L5: 19.6 | M5: -10.8 | N5: -54 | O5: -19.2 | P5: 11.1 | Q5: 898.5
A6: =B6&"-"&C6 -> y5-x21 | B6: y5 | C6: x21 | D6: c11y | E6: 14.8 | F6: 2.9 | G6: -9.2 | H6: -14.6 | I6: -2.8 | J6: 9.5 | K6: 69.9 | L6: 29.9 | M6: -25.9 | N6: -69.4 | O6: -29.7 | P6: 26.3 | Q6: 893.1
A7: =B7&"-"&C7 -> y6-x21 | B7: y6 | C7: x21 | D7: c11y | E7: 5.5 | F7: 523.6 | G7: -172.3 | H7: -22.3 | I7: -5.8 | J7: 168.3 | K7: 105.1 | L7: 61 | M7: -26.3 | N7: -104.1 | O7: -60.5 | P7: 29 | Q7: 781.8
A8: =B8&"-"&C8 -> y7-x21 | B8: y7 | C8: x21 | D8: c11y | E8: 15.6 | F8: 31.7 | G8: -6.7 | H8: -16.3 | I8: -6.1 | J8: 6.6 | K8: 119 | L8: 44.5 | M8: -4.2 | N8: -114.8 | O8: -43 | P8: 4.5 | Q8: 400
A9: =B9&"-"&C9 -> y1-x22 | B9: y1 | C9: x22 | D9: c11x | E9: 122.2 | F9: 41.6 | G9: 522.1 | H9: -102.9 | I9: -988.4 | J9: -546 | K9: 30.2 | L9: 4.5 | M9: -92.2 | N9: -29.6 | O9: -4.5 | P9: 109.6 | Q9: 407.1
A10: =B10&"-"&C10 -> y2-x22 | B10: y2 | C10: x22 | D10: c11x | E10: 131.4 | F10: 46.7 | G10: 24.4 | H10: -128.8 | I10: -45.7 | J10: -23.9 | K10: 30.2 | L10: 4.6 | M10: 0.4 | N10: -29 | O10: -4.4 | P10: 3.2 | Q10: 691.4
A11: =B11&"-"&C11 -> y3-x22 | B11: y3 | C11: x22 | D11: c11x | E11: 123 | F11: 44.2 | G11: 47.1 | H11: -120.3 | I11: -43.2 | J11: -45 | K11: 53.2 | L11: 16.9 | M11: -13.6 | N11: -51.4 | O11: -16.4 | P11: 13.7 | Q11: 702.4
A12: =B12&"-"&C12 -> y4-x22 | B12: y4 | C12: x22 | D12: c11y | E12: 13.9 | F12: 2.3 | G12: 16.3 | H12: -13.6 | I12: -2.2 | J12: -16.1 | K12: 51.4 | L12: 18.3 | M12: -10 | N12: -50.8 | O12: -18 | P12: 9.3 | Q12: 895.1
A13: =B13&"-"&C13 -> y5-x22 | B13: y5 | C13: x22 | D13: c11y | E13: 15 | F13: 2.9 | G13: 5.9 | H13: -14.6 | I13: -2.8 | J13: -4.5 | K13: 68.3 | L13: 28.7 | M13: -31.8 | N13: -62 | O13: -26.7 | P13: 34.9 | Q13: 895.1
... A115: =B115&"-"&C115 -> y10-x10 | B115: y10 | C115: x10 | D115: c4y | E115: 37.9 | F115: 5.9 | G115: 0.8 | H115: -3.8 | I115: -5.2 | J115: -0.6 | K115: 79.6 | L115: 0.5 | M115: 778.1 | N115: -48.4 | O115: 5.1 | P115: -761 | Q115: 501.9
Q116: =SUM(Q2:Q115) -> 166094.7

Sheet フーチングの検討 (2025年1月24日以降)
C2: =支点応力まとめ!A6 -> フーチング | D2: =支点応力まとめ!B6 -> 整理名称 | E2: =支点応力まとめ!C6 -> 軸 | F2: =支点応力まとめ!D6 -> 通 | G2: =支点応力まとめ!E6 -> 長期 | H2: =支点応力まとめ!F6 -> 軸 | I2: =支点応力まとめ!G6 -> 通 | J2: =支点応力まとめ!H6 -> 短期 max | ... M2: =支点応力まとめ!K6 -> 短期 min
C3: =支点応力まとめ!A7 -> 0 | D3: =支点応力まとめ!B7 -> 0 | E3: =支点応力まとめ!C7 -> 0 | F3: =支点応力まとめ!D7 -> 0 | G3: =支点応力まとめ!E7 -> 0 | H3: =支点応力まとめ!F7 -> 0 | I3: =支点応力まとめ!G7 -> 0 | J3: =支点応力まとめ!H7 -> 0 | ... M3: =支点応力まとめ!K7 -> 0
C4: =支点応力まとめ!A8 -> F10,F10A,F10B,F10C | D4: =支点応力まとめ!B8 -> F10 | E4: =支点応力まとめ!C8 -> y8 | F4: =支点応力まとめ!D8 -> x9 | G4: =支点応力まとめ!E8 -> 5244.2 | H4: =支点応力まとめ!F8 -> y2 | I4: =支点応力まとめ!G8 -> x7 | J4: =支点応力まとめ!H8 -> 6396.35 | ... M4: =支点応力まとめ!K8 -> 703.9
C5: =支点応力まとめ!A9 -> F11 | D5: =支点応力まとめ!B9 -> F11 | E5: =支点応力まとめ!C9 -> y9 | F5: =支点応力まとめ!D9 -> x9 | G5: =支点応力まとめ!E9 -> 4240.1 | H5: =支点応力まとめ!F9 -> y9 | I5: =支点応力まとめ!G9 -> x9 | J5: =支点応力まとめ!H9 -> 5163.35 | ... M5: =支点応力まとめ!K9 -> 3591
C6: =支点応力まとめ!A10 -> F20A,F20C,F20D | D6: =支点応力まとめ!B10 -> F20 | E6: =支点応力まとめ!C10 -> y7 | F6: =支点応力まとめ!D10 -> x10 | G6: =支点応力まとめ!E10 -> 3364.8 | H6: =支点応力まとめ!F10 -> y1 | I6: =支点応力まとめ!G10 -> x4 | J6: =支点応力まとめ!H10 -> 4662.95 | ... M6: =支点応力まとめ!K10 -> 1279.9
C7: =支点応力まとめ!A11 -> F21,F21B,F21C | D7: =支点応力まとめ!B11 -> F21 | E7: =支点応力まとめ!C11 -> y10 | F7: =支点応力まとめ!D11 -> x2 | G7: =支点応力まとめ!E11 -> 3192.1 | H7: =支点応力まとめ!F11 -> y1 | I7: =支点応力まとめ!G11 -> x7 | J7: =支点応力まとめ!H11 -> 4859.7 | ... M7: =支点応力まとめ!K11 -> 1365.8
C8: =支点応力まとめ!A12 -> F30,F30B,F30C | D8: =支点応力まとめ!B12 -> F30 | E8: =支点応力まとめ!C12 -> y9 | F8: =支点応力まとめ!D12 -> x10 | G8: =支点応力まとめ!E12 -> 2471.5 | H8: =支点応力まとめ!F12 -> y10 | I8: =支点応力まとめ!G12 -> x7 | J8: =支点応力まとめ!H12 -> 4174 | ... M8: =支点応力まとめ!K12 -> 623.1
C9: =支点応力まとめ!A13 -> 0 | D9: =支点応力まとめ!B13 -> 0 | E9: =支点応力まとめ!C13 -> 0 | F9: =支点応力まとめ!D13 -> 0 | G9: =支点応力まとめ!E13 -> 0 | H9: =支点応力まとめ!F13 -> 0 | I9: =支点応力まとめ!G13 -> 0 | J9: =支点応力まとめ!H13 -> 0 | ... M9: =支点応力まとめ!K13 -> 0
C10: =支点応力まとめ!A14 -> 0 | D10: =支点応力まとめ!B14 -> 0 | E10: =支点応力まとめ!C14 -> 0 | F10: =支点応力まとめ!D14 -> 0 | G10: =支点応力まとめ!E14 -> 0 | H10: =支点応力まとめ!F14 -> 0 | I10: =支点応力まとめ!G14 -> 0 | J10: =支点応力まとめ!H14 -> 0 | ... M10: =支点応力まとめ!K14 -> 0
C11: =支点応力まとめ!A15 -> 0 | D11: =支点応力まとめ!B15 -> 0 | E11: =支点応力まとめ!C15 -> 0 | F11: =支点応力まとめ!D15 -> 0 | G11: =支点応力まとめ!E15 -> 0 | H11: =支点応力まとめ!F15 -> 0 | I11: =支点応力まとめ!G15 -> 0 | J11: =支点応力まとめ!H15 -> 0 | ... M11: =支点応力まとめ!K15 -> 0
C12: =支点応力まとめ!A16 -> 0 | D12: =支点応力まとめ!B16 -> 0 | E12: =支点応力まとめ!C16 -> 0 | F12: =支点応力まとめ!D16 -> 0 | G12: =支点応力まとめ!E16 -> 0 | H12: =支点応力まとめ!F16 -> 0 | I12: =支点応力まとめ!G16 -> 0 | J12: =支点応力まとめ!H16 -> 0 | ... M12: =支点応力まとめ!K16 -> 0
C13: =支点応力まとめ!A17 -> 0 | D13: =支点応力まとめ!B17 -> 0 | E13: =支点応力まとめ!C17 -> 0 | F13: =支点応力まとめ!D17 -> 0 | G13: =支点応力まとめ!E17 -> 0 | H13: =支点応力まとめ!F17 -> 0 | I13: =支点応力まとめ!G17 -> 0 | J13: =支点応力まとめ!H17 -> 0 | ... M13: =支点応力まとめ!K17 -> 0
C16: 0.76 | D16: Fc27のせん断許容応力度 | I16: 1.14 | J16: Fc27短期許容せん断応力度
C17: 0.215 | D17: 鉄筋の長期許容応力度(kN/mm^2) | I17: 0.39 | J17: 鉄筋の長期許容応力度(kN/mm^2)
C18: 0.195 | D18: あばら筋のせん断補強筋用応力度 | I18: 0.295 | J18: あばら筋のせん断補強筋用応力度
C19: 21700 | D19: Fc21のヤング係数(N/mm^2) | J19: at：主筋断面積
D20: Q_d：必要せん断力 | J20: τd：存在せん断応力
D21: at_d:必要主筋断面積 | J21: dc：かぶり厚
B23: ○二本杭フーチング検討諸元
B24: 記号 | C24: B(mm) | D24: D(mm) | E24: 主筋 | H24: スターラップ | L24: かぶり | M24: せん断 (kN) | N24: 杭あき (mm) | O24: ねじり T(kNm) | V24: 曲げの検討 | Z24: せん断力の検討 | AF24: ねじりの検討 | AL24: あばら筋比0.2%の検討
E25: 名称 | F25: 本数 | G25: 断面積 (mm2) | H25: 名称 | I25: 組 | J25: 断面積 (mm2) | K25: ピッチ | L25: dc(mm) | V25: M | W25: at_d | X25: at | Y25: at_d/at | Z25: Q_d | AA25: τd | AB25: pw | AC25: α | AD25: τa | AE25: τd/τa | AF25: A: T/M | AG25: B: 0.4/ (1+w) | AH25: A/B<1.0 | AI25: T0 | AJ25: Q0 | AK25: (T/T0)2+(Q/Q0)2<1.0 | AL25: ピッチp (mm) | AM25: あばら筋 断面積 A(mm2) | AN25: 幅B (mm) | AO25: あばら筋比 | AP25: 0.2/ あばら筋比
B26: F2長期 | C26: 3500 | D26: 1800 | E26: =F26&"-D29" -> 33-D29 | F26: 33 | G26: 642 | H26: =I26&"-D19@"&K26 -> 4-D19@200 | I26: 4 | J26: 286 | K26: 200 | L26: 70 | M26: 10253 | N26: 2500 | O26: 1400 | V26: =Z26*N26/2/1000 -> 6408.125 | W26: =V26*1000/$C$17/((D26-L26)*0.875) -> 19689.666 | X26: =G26*F26 -> 21186 | Y26: =W26/X26 -> 0.92937159 | Z26: =M26/2 -> 5126.5 | AA26: =Z26*1000/C26/((D26-L26-150)*0.875) -> 1.0594678 | AB26: =J26*I26/C26/K26 -> 0.0016342857 | AC26: =MIN( 4/((V26/Z26/(D26/1000))+1), 2 ) -> 2 | AD26: =(AC26*$C$16+0.5*$C$18*1000*(AB26-0.002)) -> 1.4843429 | AE26: =AA26/AD26 -> 0.71376221
B27: F2短期 | C27: =C26 -> 3500 | D27: =D26 -> 1800 | E27: =E26 -> 33-D29 | F27: =F26 -> 33 | G27: =$G$26 -> 642 | H27: =H26 -> 4-D19@200 | I27: =I26 -> 4 | J27: =J26 -> 286 | K27: =K26 -> 200 | L27: 70 | M27: 11892 | N27: =N26 -> 2500 | O27: =O26 -> 1400 | P27: 基礎を梁に見立ててせん断力の検討に、 αを考慮する場合は、 短期設計用せん断力の地震時せん断力を 1.5倍する必要がある。 | V27: =Z27*N27/2/1000 -> 7432.5 | W27: =V27*1000/$I$17/((D27-L27)*0.875) -> 12589.722 | X27: =G27*F27 -> 21186 | Y27: =W27/X27 -> 0.59424726 | Z27: =M27/2 -> 5946 | AA27: =Z27*1000/C27/((D27-L27-150)*0.875) -> 1.2288298 | AB27: =J27*I27/C27/K27 -> 0.0016342857 | AC27: =MIN( 4/((V27/Z27/(D27/1000))+1), 2 ) -> 2 | AD27: =(AC27*$I$16+0.5*$C$18*1000*(AB27-0.002)) -> 2.2443429 | AE27: =AA27/AD27 -> 0.54752319 | AF27: =O27/V27 -> 0.18836192 | AG27: =0.4/(1+K26/C26) -> 0.37837838 | AH27: =AF27/AG27 -> 0.49781366 | AI27: =POWER(MIN(C27:D27),2)*MAX(C27:D27)*1.15*$I$16/3000000 -> 4955.58 | AJ27: =C27*(D27*7/8)*AC27*$I$16/1000 -> 12568.5 | AK27: =POWER(O27/AI27,2)+POWER(Z27/AJ27,2) -> 0.30362356 | AL27: =K26 -> 200 | AM27: =J26*I26 -> 1144 | AN27: =C26 -> 3500 | AO27: =AM27/AL27/AN27*100 -> 0.16342857 | AP27: =0.2/AO27 -> 1.2237762
B28: F2短期(上端) | C28: =C27 -> 3500 | D28: =D27 -> 1800 | E28: =E27 -> 33-D29 | F28: =F27 -> 33 | G28: =$G$26 -> 642 | H28: =H27 -> 4-D19@200 | I28: =I27 -> 4 | J28: =J27 -> 286 | K28: =K27 -> 200 | L28: 70 | M28: 0.1 | N28: =N27 -> 2500 | O28: 700 | V28: =Z28*N28/2/1000 -> 0.0625 | W28: =V28*1000/$I$17/((D28-L28)*0.875) -> 0.10586716 | X28: =G28*F28 -> 21186 | Y28: =W28/X28 -> 4.9970338e-06 | Z28: =M28/2 -> 0.05 | AA28: =Z28*1000/C28/((D28-L28-150)*0.875) -> 1.0333247e-05 | AB28: =J28*I28/C28/K28 -> 0.0016342857 | AC28: =MIN( 4/((V28/Z28/(D28/1000))+1), 2 ) -> 2 | AD28: =(AC28*$I$16+0.5*$C$18*1000*(AB28-0.002)) -> 2.2443429 | AE28: =AA28/AD28 -> 4.6041304e-06
B29: F12長期 | C29: 2200 | D29: 1700 | E29: =F29&"-D25" -> 20-D25 | F29: 20 | G29: 507 | H29: =I29&"-D16@"&K29 -> 4-D16@175 | I29: 4 | J29: 198 | K29: 175 | L29: 70 | M29: 5869 | N29: 2000 | O29: 1400 | V29: =Z29*N29/2/1000 -> 2934.5 | W29: =V29*1000/$C$17/((D29-L29)*0.875) -> 9569.7369 | X29: =G29*F29 -> 10140 | Y29: =W29/X29 -> 0.94376103 | Z29: =M29/2 -> 2934.5 | AA29: =Z29*1000/C29/((D29-L29-150)*0.875) -> 1.0300105 | AB29: =J29*I29/C29/K29 -> 0.0020571429 | AC29: =MIN( 4/((V29/Z29/(D29/1000))+1), 2 ) -> 2 | AD29: =(AC29*$C$16+0.5*$C$18*1000*(AB29-0.002)) -> 1.5255714 | AE29: =AA29/AD29 -> 0.67516375
B30: F12短期最大 | C30: =C29 -> 2200 | D30: =D29 -> 1700 | E30: =E29 -> 20-D25 | F30: =F29 -> 20 | G30: =G29 -> 507 | H30: =H29 -> 4-D16@175 | I30: =I29 -> 4 | J30: =J29 -> 198 | ... L30: =L29 -> 70 | M30: 7770 | N30: =N29 -> 2000 | O30: =O29 -> 1400 | V30: =Z30*N30/2/1000 -> 3885 | W30: =V30*1000/$I$17/((D30-L30)*0.875) -> 6984.4266 | X30: =G30*F30 -> 10140 | Y30: =W30/X30 -> 0.68879947 | Z30: =M30/2 -> 3885 | AA30: =Z30*1000/C30/((D30-L30-150)*0.875) -> 1.3636364 | AB30: =J30*I30/C30/K30 -> 0.0020571429 | AC30: =MIN( 4/((V30/Z30/(D30/1000))+1), 2 ) -> 2 | AD30: =(AC30*$I$16+0.5*$C$18*1000*(AB30-0.002)) -> 2.2855714 | AE30: =AA30/AD30 -> 0.5966282 | AF30: =O30/V30 -> 0.36036036 | AG30: =0.4/(1+K29/C29) -> 0.37052632 | AH30: =AF30/AG30 -> 0.97256347 | AI30: =POWER(MIN(C30:D30),2)*MAX(C30:D30)*1.15*$I$16/3000000 -> 2778.446 | AJ30: =C30*(D30*7/8)*AC30*$I$16/1000 -> 7461.3 | AK30: =POWER(O30/AI30,2)+POWER(Z30/AJ30,2) -> 0.52500852 | AL30: =K29 -> 175 | AM30: =J29*I29 -> 792 | AN30: =C29 -> 2200 | AO30: =AM30/AL30/AN30*100 -> 0.20571429 | AP30: =0.2/AO30 -> 0.97222222
